Workbook
Name L_Topic: '01_Master_Data'!$A$4:INDEX('01_Master_Data'!$A$4:$A$103,COUNTA('01_Master_Data'!$A$4:$A$103))
Name L_Department: '01_Master_Data'!$B$4:INDEX('01_Master_Data'!$B$4:$B$103,COUNTA('01_Master_Data'!$B$4:$B$103))
Name L_Location: '01_Master_Data'!$C$4:INDEX('01_Master_Data'!$C$4:$C$103,COUNTA('01_Master_Data'!$C$4:$C$103))
Name L_Safety_Category: '01_Master_Data'!$D$4:INDEX('01_Master_Data'!$D$4:$D$103,COUNTA('01_Master_Data'!$D$4:$D$103))
Name L_Action_Required: '01_Master_Data'!$E$4:INDEX('01_Master_Data'!$E$4:$E$103,COUNTA('01_Master_Data'!$E$4:$E$103))
Name L_Risk_Level: '01_Master_Data'!$F$4:INDEX('01_Master_Data'!$F$4:$F$103,COUNTA('01_Master_Data'!$F$4:$F$103))
Name L_Assessment_Type: '01_Master_Data'!$G$4:INDEX('01_Master_Data'!$G$4:$G$103,COUNTA('01_Master_Data'!$G$4:$G$103))
Name L_Approval_Status: '01_Master_Data'!$H$4:INDEX('01_Master_Data'!$H$4:$H$103,COUNTA('01_Master_Data'!$H$4:$H$103))
Name L_Training_Type: '01_Master_Data'!$I$4:INDEX('01_Master_Data'!$I$4:$I$103,COUNTA('01_Master_Data'!$I$4:$I$103))
Name L_Mode: '01_Master_Data'!$J$4:INDEX('01_Master_Data'!$J$4:$J$103,COUNTA('01_Master_Data'!$J$4:$J$103))
Name L_Status: '01_Master_Data'!$K$4:INDEX('01_Master_Data'!$K$4:$K$103,COUNTA('01_Master_Data'!$K$4:$K$103))
Name L_Assessment_Result: '01_Master_Data'!$L$4:INDEX('01_Master_Data'!$L$4:$L$103,COUNTA('01_Master_Data'!$L$4:$L$103))
Name L_Observation_Type: '01_Master_Data'!$M$4:INDEX('01_Master_Data'!$M$4:$M$103,COUNTA('01_Master_Data'!$M$4:$M$103))
Name L_Category: '01_Master_Data'!$N$4:INDEX('01_Master_Data'!$N$4:$N$103,COUNTA('01_Master_Data'!$N$4:$N$103))
Name L_Overall_Rating: '01_Master_Data'!$O$4:INDEX('01_Master_Data'!$O$4:$O$103,COUNTA('01_Master_Data'!$O$4:$O$103))
Name L_Frequency: '01_Master_Data'!$P$4:INDEX('01_Master_Data'!$P$4:$P$103,COUNTA('01_Master_Data'!$P$4:$P$103))
Name L_Type: '01_Master_Data'!$Q$4:INDEX('01_Master_Data'!$Q$4:$Q$103,COUNTA('01_Master_Data'!$Q$4:$Q$103))
Name L_Distribution_Method: '01_Master_Data'!$R$4:INDEX('01_Master_Data'!$R$4:$R$103,COUNTA('01_Master_Data'!$R$4:$R$103))
Name L_Status_2: '01_Master_Data'!$S$4:INDEX('01_Master_Data'!$S$4:$S$103,COUNTA('01_Master_Data'!$S$4:$S$103))
Name L_Drill_Type: '01_Master_Data'!$T$4:INDEX('01_Master_Data'!$T$4:$T$103,COUNTA('01_Master_Data'!$T$4:$T$103))
Name L_Overall_Rating_2: '01_Master_Data'!$U$4:INDEX('01_Master_Data'!$U$4:$U$103,COUNTA('01_Master_Data'!$U$4:$U$103))
Name L_Status_3: '01_Master_Data'!$V$4:INDEX('01_Master_Data'!$V$4:$V$103,COUNTA('01_Master_Data'!$V$4:$V$103))
Name L_Audit_Type: '01_Master_Data'!$W$4:INDEX('01_Master_Data'!$W$4:$W$103,COUNTA('01_Master_Data'!$W$4:$W$103))
Name L_Status_4: '01_Master_Data'!$X$4:INDEX('01_Master_Data'!$X$4:$X$103,COUNTA('01_Master_Data'!$X$4:$X$103))
Name L_Visit_Type: '01_Master_Data'!$Y$4:INDEX('01_Master_Data'!$Y$4:$Y$103,COUNTA('01_Master_Data'!$Y$4:$Y$103))
Name L_Status_5: '01_Master_Data'!$Z$4:INDEX('01_Master_Data'!$Z$4:$Z$103,COUNTA('01_Master_Data'!$Z$4:$Z$103))
Name L_Violation_Type: '01_Master_Data'!$AA$4:INDEX('01_Master_Data'!$AA$4:$AA$103,COUNTA('01_Master_Data'!$AA$4:$AA$103))
Name L_Action_Taken: '01_Master_Data'!$AB$4:INDEX('01_Master_Data'!$AB$4:$AB$103,COUNTA('01_Master_Data'!$AB$4:$AB$103))
Name L_Offense_Level: '01_Master_Data'!$AC$4:INDEX('01_Master_Data'!$AC$4:$AC$103,COUNTA('01_Master_Data'!$AC$4:$AC$103))
Name L_Status_6: '01_Master_Data'!$AD$4:INDEX('01_Master_Data'!$AD$4:$AD$103,COUNTA('01_Master_Data'!$AD$4:$AD$103))
Name L_Award_Category: '01_Master_Data'!$AE$4:INDEX('01_Master_Data'!$AE$4:$AE$103,COUNTA('01_Master_Data'!$AE$4:$AE$103))
Name L_Reward_Type: '01_Master_Data'!$AF$4:INDEX('01_Master_Data'!$AF$4:$AF$103,COUNTA('01_Master_Data'!$AF$4:$AF$103))
Name L_Status_7: '01_Master_Data'!$AG$4:INDEX('01_Master_Data'!$AG$4:$AG$103,COUNTA('01_Master_Data'!$AG$4:$AG$103))
Name L_Severity: '01_Master_Data'!$AH$4:INDEX('01_Master_Data'!$AH$4:$AH$103,COUNTA('01_Master_Data'!$AH$4:$AH$103))
Name L_Resolution: '01_Master_Data'!$AI$4:INDEX('01_Master_Data'!$AI$4:$AI$103,COUNTA('01_Master_Data'!$AI$4:$AI$103))
Name L_Test_Type: '01_Master_Data'!$AJ$4:INDEX('01_Master_Data'!$AJ$4:$AJ$103,COUNTA('01_Master_Data'!$AJ$4:$AJ$103))
Name L_Result: '01_Master_Data'!$AK$4:INDEX('01_Master_Data'!$AK$4:$AK$103,COUNTA('01_Master_Data'!$AK$4:$AK$103))
Name L_Permit_Type_Audited: '01_Master_Data'!$AL$4:INDEX('01_Master_Data'!$AL$4:$AL$103,COUNTA('01_Master_Data'!$AL$4:$AL$103))
Name L_Verdict: '01_Master_Data'!$AM$4:INDEX('01_Master_Data'!$AM$4:$AM$103,COUNTA('01_Master_Data'!$AM$4:$AM$103))
Name L_Source: '01_Master_Data'!$AN$4:INDEX('01_Master_Data'!$AN$4:$AN$103,COUNTA('01_Master_Data'!$AN$4:$AN$103))
Name L_Source_2: '01_Master_Data'!$AO$4:INDEX('01_Master_Data'!$AO$4:$AO$103,COUNTA('01_Master_Data'!$AO$4:$AO$103))
Name L_Severity_2: '01_Master_Data'!$AP$4:INDEX('01_Master_Data'!$AP$4:$AP$103,COUNTA('01_Master_Data'!$AP$4:$AP$103))
Name L_Status_8: '01_Master_Data'!$AQ$4:INDEX('01_Master_Data'!$AQ$4:$AQ$103,COUNTA('01_Master_Data'!$AQ$4:$AQ$103))
Name L_Immediate_Action: '01_Master_Data'!$AR$4:INDEX('01_Master_Data'!$AR$4:$AR$103,COUNTA('01_Master_Data'!$AR$4:$AR$103))
Name FY_Start: '08_Settings'!$C$11
Name Man_Hours: '08_Settings'!$C$12
Name TRIR_Mult: '08_Settings'!$C$13
Name LTIFR_Mult: '08_Settings'!$C$14
Name Tgt_ObsClosure: '08_Settings'!$C$17
Name Tgt_Training: '08_Settings'!$C$18
Name Tgt_CAClosure: '08_Settings'!$C$19
Name Tgt_TRIR: '08_Settings'!$C$20
Name RAG_Amber: '08_Settings'!$C$21
Name L_Area: '01_Master_Data'!$AT$4:INDEX('01_Master_Data'!$AT$4:$AT$103,COUNTA('01_Master_Data'!$AT$4:$AT$103))
Name L_ProdLine: '01_Master_Data'!$AU$4:INDEX('01_Master_Data'!$AU$4:$AU$103,COUNTA('01_Master_Data'!$AU$4:$AU$103))
Name L_Shift: '01_Master_Data'!$AV$4:INDEX('01_Master_Data'!$AV$4:$AV$103,COUNTA('01_Master_Data'!$AV$4:$AV$103))
Name L_IncidentType: '01_Master_Data'!$AW$4:INDEX('01_Master_Data'!$AW$4:$AW$103,COUNTA('01_Master_Data'!$AW$4:$AW$103))
Name L_IncClass: '01_Master_Data'!$AX$4:INDEX('01_Master_Data'!$AX$4:$AX$103,COUNTA('01_Master_Data'!$AX$4:$AX$103))
Name L_PersonType: '01_Master_Data'!$AY$4:INDEX('01_Master_Data'!$AY$4:$AY$103,COUNTA('01_Master_Data'!$AY$4:$AY$103))
Name L_BodyPart: '01_Master_Data'!$AZ$4:INDEX('01_Master_Data'!$AZ$4:$AZ$103,COUNTA('01_Master_Data'!$AZ$4:$AZ$103))

Sheet 06_Executive_Dashboard
A1: 🏆 EXECUTIVE EHS DASHBOARD
A2: Corporate leading & lagging indicators · TRIR / LTIFR / Incident Pyramid / RAG · auto-calculated from all registers
B4: 🎯 TRIR | F4: 📉 LTIFR | J4: 🚨 TOTAL INCIDENTS | N4: 👀 NEAR MISS
B5: =IFERROR((COUNTIF('Incident'!N$6:N$506,"Medical Treatment")+COUNTIF('Incident'!N$6:N$506,"Restricted Work")+COUNTIF('Incident'!N$6:N$506,"Lost Time Injury")+COUNTIF('Incident'!N$6:N$506,"Fatality"))*TRIR_Mult/Man_Hours,0) | F5: =IFERROR((COUNTIF('Incident'!N$6:N$506,"Lost Time Injury")+COUNTIF('Incident'!N$6:N$506,"Fatality"))*LTIFR_Mult/Man_Hours,0) | J5: =COUNTA('Incident'!B$6:B$506) | N5: =COUNTIF('Incident'!N$6:N$506,"Near Miss")
B7: ✅ OBS CLOSURE | F7: 🎓 TRAINING COMPL. | J7: 🛠️ CA CLOSURE | N7: 📅 LOST DAYS
B8: =IFERROR(COUNTIF('HSE Observations'!M$6:M$506,"Completed")/COUNTA('HSE Observations'!B$6:B$506),0) | F8: =IFERROR(COUNTIF('Training'!N$6:N$506,"Completed")/COUNTA('Training'!B$6:B$506),0) | J8: =IFERROR(COUNTIF('Corrective Actions'!N$6:N$506,"Completed")/COUNTA('Corrective Actions'!B$6:B$506),0) | N8: =SUM('Incident'!V$6:V$506)
B11: 🔺 Incident Pyramid (Heinrich)
B12: Level | C12: Count
B13: Fatality | C13: =COUNTIF('Incident'!N$6:N$506,"Fatality")
B14: Lost Time Injury | C14: =COUNTIF('Incident'!N$6:N$506,"Lost Time Injury")
B15: Restricted Work | C15: =COUNTIF('Incident'!N$6:N$506,"Restricted Work")
B16: Medical Treatment | C16: =COUNTIF('Incident'!N$6:N$506,"Medical Treatment")
B17: First Aid | C17: =COUNTIF('Incident'!N$6:N$506,"First Aid")
B18: Near Miss | C18: =COUNTIF('Incident'!N$6:N$506,"Near Miss")
B19: At-Risk Observations | C19: =COUNTIF('HSE Observations'!E$6:E$506,"Unsafe Act")+COUNTIF('HSE Observations'!E$6:E$506,"Unsafe Condition")+COUNTA('Unsafe Acts'!B$6:B$506)+COUNTA('Unsafe Conditions'!B$6:B$506)
B22: 📈 12-Month Incident Trend
B23: Jan | C23: Feb | D23: Mar | E23: Apr | F23: May | G23: Jun | H23: Jul | I23: Aug | J23: Sep | K23: Oct | L23: Nov | M23: Dec
B24: =COUNTIF('Incident'!D$6:D$506,"Jan") | C24: =COUNTIF('Incident'!D$6:D$506,"Feb") | D24: =COUNTIF('Incident'!D$6:D$506,"Mar") | E24: =COUNTIF('Incident'!D$6:D$506,"Apr") | F24: =COUNTIF('Incident'!D$6:D$506,"May") | G24: =COUNTIF('Incident'!D$6:D$506,"Jun") | H24: =COUNTIF('Incident'!D$6:D$506,"Jul") | I24: =COUNTIF('Incident'!D$6:D$506,"Aug") | J24: =COUNTIF('Incident'!D$6:D$506,"Sep") | K24: =COUNTIF('Incident'!D$6:D$506,"Oct") | L24: =COUNTIF('Incident'!D$6:D$506,"Nov") | M24: =COUNTIF('Incident'!D$6:D$506,"Dec")
B42: 🟢 Leading Indicators (Activity) | F42: 🔴 Lagging Indicators (Outcome) | K42: 🚦 RAG Compliance Scorecard
B43: Indicator | C43: Count | F43: Indicator | G43: Count | K43: Metric | L43: Actual | M43: Target | N43: Status
B44: Observations | C44: =COUNTA('HSE Observations'!B$6:B$506) | F44: Fatality | G44: =COUNTIF('Incident'!N$6:N$506,"Fatality") | K44: TRIR | L44: =IFERROR((COUNTIF('Incident'!N$6:N$506,"Medical Treatment")+COUNTIF('Incident'!N$6:N$506,"Restricted Work")+COUNTIF('Incident'!N$6:N$506,"Lost Time Injury")+COUNTIF('Incident'!N$6:N$506,"Fatality"))*TRIR_Mult/Man_Hours,0) | M44: =Tgt_TRIR | N44: =IF(IFERROR((COUNTIF('Incident'!N$6:N$506,"Medical Treatment")+COUNTIF('Incident'!N$6:N$506,"Restricted Work")+COUNTIF('Incident'!N$6:N$506,"Lost Time Injury")+COUNTIF('Incident'!N$6:N$506,"Fatality"))*TRIR_Mult/Man_Hours,0)<=Tgt_TRIR,"🟢 GREEN",IF(IFERROR((COUNTIF('Incident'!N$6:N$506,"Medical Treatment")+COUNTIF('Incident'!N$6:N$506,"Restricted Work")+COUNTIF('Incident'!N$6:N$506,"Lost Time Injury")+COUNTIF('Incident'!N$6:N$506,"Fatality"))*TRIR_Mult/Man_Hours,0)<=Tgt_TRIR/RAG_Amber,"🟡 AMBER","🔴 RED"))
B45: Toolbox Talks | C45: =COUNTA('Toolbox Talks'!B$6:B$506) | F45: Lost Time Injury | G45: =COUNTIF('Incident'!N$6:N$506,"Lost Time Injury") | K45: Observation Closure | L45: =IFERROR(COUNTIF('HSE Observations'!M$6:M$506,"Completed")/COUNTA('HSE Observations'!B$6:B$506),0) | M45: =Tgt_ObsClosure | N45: =IF(IFERROR(COUNTIF('HSE Observations'!M$6:M$506,"Completed")/COUNTA('HSE Observations'!B$6:B$506),0)>=Tgt_ObsClosure,"🟢 GREEN",IF(IFERROR(COUNTIF('HSE Observations'!M$6:M$506,"Completed")/COUNTA('HSE Observations'!B$6:B$506),0)>=Tgt_ObsClosure*RAG_Amber,"🟡 AMBER","🔴 RED"))
B46: Trainings | C46: =COUNTA('Training'!B$6:B$506) | F46: Restricted Work | G46: =COUNTIF('Incident'!N$6:N$506,"Restricted Work") | K46: Training Compliance | L46: =IFERROR(COUNTIF('Training'!N$6:N$506,"Completed")/COUNTA('Training'!B$6:B$506),0) | M46: =Tgt_Training | N46: =IF(IFERROR(COUNTIF('Training'!N$6:N$506,"Completed")/COUNTA('Training'!B$6:B$506),0)>=Tgt_Training,"🟢 GREEN",IF(IFERROR(COUNTIF('Training'!N$6:N$506,"Completed")/COUNTA('Training'!B$6:B$506),0)>=Tgt_Training*RAG_Amber,"🟡 AMBER","🔴 RED"))
B47: Inspections | C47: =COUNTA('Workplace Inspections'!B$6:B$506)+COUNTA('Equipment Inspections'!B$6:B$506)+COUNTA('Safety Walkthroughs'!B$6:B$506) | F47: Medical Treatment | G47: =COUNTIF('Incident'!N$6:N$506,"Medical Treatment") | K47: CA Closure | L47: =IFERROR(COUNTIF('Corrective Actions'!N$6:N$506,"Completed")/COUNTA('Corrective Actions'!B$6:B$506),0) | M47: =Tgt_CAClosure | N47: =IF(IFERROR(COUNTIF('Corrective Actions'!N$6:N$506,"Completed")/COUNTA('Corrective Actions'!B$6:B$506),0)>=Tgt_CAClosure,"🟢 GREEN",IF(IFERROR(COUNTIF('Corrective Actions'!N$6:N$506,"Completed")/COUNTA('Corrective Actions'!B$6:B$506),0)>=Tgt_CAClosure*RAG_Amber,"🟡 AMBER","🔴 RED"))
B48: Audits | C48: =COUNTA('Internal Audits'!B$6:B$506)+COUNTA('External Audits'!B$6:B$506) | F48: First Aid | G48: =COUNTIF('Incident'!N$6:N$506,"First Aid")
B49: Emergency Drills | C49: =COUNTA('Emergency Drills'!B$6:B$506) | F49: Near Miss | G49: =COUNTIF('Incident'!N$6:N$506,"Near Miss")
B50: PTW Audits | C50: =COUNTA('PTW Audits'!B$6:B$506)

Sheet 01_Master_Data
A1: 📚 MASTER DATA — Single source of truth for all dropdown lists
A2: Add / edit items directly under each heading. Dropdowns update automatically (up to 100 items per list).
A3: Topic | B3: Department | C3: Location | D3: Safety_Category | E3: Action_Required | F3: Risk_Level | G3: Assessment_Type | H3: Approval_Status | I3: Training_Type | J3: Mode | K3: Status | L3: Assessment_Result | M3: Observation_Type | N3: Category | O3: Overall_Rating | P3: Frequency | Q3: Type | R3: Distribution_Method | S3: Status_2 | T3: Drill_Type | U3: Overall_Rating_2 | V3: Status_3 | W3: Audit_Type | X3: Status_4 | Y3: Visit_Type | Z3: Status_5 | AA3: Violation_Type | AB3: Action_Taken | AC3: Offense_Level | AD3: Status_6 | AE3: Award_Category | AF3: Reward_Type | AG3: Status_7 | AH3: Severity | AI3: Resolution | AJ3: Test_Type | AK3: Result | AL3: Permit_Type_Audited | AM3: Verdict | AN3: Source | AO3: Source_2 | AP3: Severity_2 | AQ3: Status_8 | AR3: Immediate_Action | AT3: Area | AU3: ProdLine | AV3: Shift | AW3: IncidentType | AX3: IncClass | AY3: PersonType | AZ3: BodyPart | BA3: RootCause | BB3: RiskRating | BC3: IncStatus
A4: PPE Usage | B4: Operations | C4: Plant A | D4: BBS | E4: Yes | F4: High | G4: HIRA | H4: Approved | I4: Induction | J4: Internal | K4: Completed | L4: Pass | M4: Safe Act | N4: BBS | O4: Satisfactory | P4: Weekly | Q4: Safety Alert | R4: Email | S4: Issued | T4: Fire Evacuation | U4: Satisfactory | V4: Completed | W4: System Audit | X4: Completed | Y4: Site Walk | Z4: Completed | AA4: PPE Violation | AB4: Verbal Warning | AC4: 1st Offense | AD4: Completed | AE4: Safe Worker of Month | AF4: Certificate | AG4: Presented | AH4: Critical | AI4: Resolved | AJ4: Pre-Shift | AK4: Negative | AL4: Hot Work | AM4: Compliant | AN4: Audit Finding | AO4: Internal Audit | AP4: Major | AQ4: Closed | AR4: Corrected Immediately | AT4: Production | AU4: Line 1 | AV4: Shift A | AW4: Injury/Illness | AX4: Near Miss | AY4: Employee | AZ4: Head | BA4: Human Error | BB4: Critical | BC4: Open
A5: Fire Safety | B5: Maintenance | C5: Plant B | D5: HIRA | E5: No | F5: Medium | G5: Task RA | H5: Pending Review | I5: Refresher | J5: External | K5: In Progress | L5: Fail | M5: Unsafe Act | N5: General | O5: Needs Improvement | P5: Monthly | Q5: Bulletin | R5: Notice Board | S5: Acknowledged | T5: Chemical Spill | U5: Good | V5: Action Pending | W5: Compliance Audit | X5: In Progress | Y5: Plant Visit | Z5: Action Pending | AA5: Safety Rule Breach | AB5: Written Warning | AC5: 2nd Offense | AD5: Under Review | AE5: Best Safety Suggestion | AF5: Trophy | AG5: Scheduled | AH5: High | AI5: Under Investigation | AJ5: Random | AK5: Positive | AL5: Confined Space | AM5: Non-Compliant | AN5: Inspection Finding | AO5: External Audit | AP5: Minor | AQ5: Open | AR5: Action Raised | AT5: Warehouse | AU5: Line 2 | AV5: Shift B | AW5: Property Damage | AX5: First Aid | AY5: Contractor | AZ5: Eye | BA5: Unsafe Act | BB5: High | BC5: In Progress
A6: Working at Heights | B6: Engineering | C6: Warehouse | D6: Training | F6: Low | G6: JSA | H6: Revision Required | I6: Advanced | J6: Online | K6: Overdue | L6: N/A | M6: Safe Condition | N6: PPE | O6: Unsatisfactory | P6: Quarterly | Q6: Toolbox Topic | R6: Toolbox Talk | S6: Closed | T6: Medical Emergency | U6: Excellent | V6: Rescheduled | W6: Process Audit | X6: Scheduled | Y6: Safety Observation | AA6: Permit Violation | AB6: Suspension | AC6: 3rd Offense | AD6: Appealed | AE6: Zero Incident Award | AF6: Cash Bonus | AG6: Nominated | AH6: Medium | AI6: Permanent Fix Applied | AJ6: Post-Incident | AL6: Working at Height | AM6: Partially Compliant | AN6: Incident Follow-up | AO6: PTW Audit | AP6: Observation | AQ6: Under Review | AR6: Under Review | AT6: Utilities | AU6: Line 3 | AV6: Shift C | AW6: Environmental | AX6: Medical Treatment | AY6: Visitor | AZ6: Hand/Finger | BA6: Unsafe Condition | BB6: Medium | BC6: Closed
A7: Manual Handling | B7: Construction | C7: Workshop | D7: Audit | G7: HAZOP | H7: Rejected | I7: Certification | J7: On-the-Job | K7: Pending | M7: Unsafe Condition | N7: Housekeeping | O7: Good | P7: Ad-hoc | Q7: Lesson Learned | R7: App Notification | T7: Earthquake | U7: Needs Improvement | W7: Theme Audit | Y7: Contractor Review | AA7: Substance Abuse | AB7: Termination | AC7: Repeat | AE7: HSE Champion | AF7: Gift Voucher | AH7: Low | AJ7: Reasonable Suspicion | AL7: Excavation | AN7: Observation Follow-up | AO7: Workplace Inspection | AQ7: Overdue | AR7: Pending | AT7: QC Lab | AU7: Line 4 | AV7: General | AW7: Fire | AX7: Restricted Work | AY7: Third Party | AZ7: Arm | BA7: Inadequate Procedure | BB7: Low | BC7: Overdue
A8: Electrical Safety | B8: Safety | C8: Field Site | D8: General | G8: What-If | I8: Awareness | K8: Cancelled | M8: Near Miss | N8: Ergonomics | O8: Excellent | P8: Annual | Q8: Best Practice | R8: All Channels | T8: Gas Leak | W8: Surveillance | Y8: Project Visit | AA8: Reckless Behavior | AB8: Retraining | AE8: Best Department | AF8: Recognition Letter | AL8: Electrical | AN8: Management Review | AO8: Customer Audit | AT8: Admin Block | AU8: PET Line | AW8: Chemical Spill | AX8: Lost Time Injury | AZ8: Foot/Leg | BA8: Lack of Training
A9: Chemical Safety | B9: Logistics | C9: Control Room | D9: Emergency | G9: Bow Tie | I9: Competency | N9: Fire Safety | Q9: Advisory | T9: Confined Space Rescue | Y9: Emergency Review | AA9: Unauthorized Work | AB9: Fine | AE9: Safety Innovation | AF9: Team Lunch | AL9: Cold Work | AN9: Drill Finding | AO9: Regulatory Inspection | AT9: Loading Bay | AU9: Can Line | AW9: Vehicle | AX9: Fatality | AZ9: Back | BA9: Equipment Failure
A10: Housekeeping | B10: Quality | C10: Office | D10: PPE | N10: Environment | T10: Bomb Threat | AA10: Tampering | AE10: Observation Champion | AL10: Lifting | AT10: Tank Farm | AU10: Syrup Room | AW10: Process Safety | AZ10: Torso | BA10: PPE Not Used
A11: Heat Stress | B11: Admin | C11: Tank Farm | D11: Environment | T11: Natural Disaster | AT11: ETP Plant | AU11: CIP System | AW11: Security | AZ11: Multiple | BA11: Poor Housekeeping
A12: Slip Trip Fall | B12: Projects | AT12: Boiler House | AU12: Blow Molding | AZ12: None / NA | BA12: Design Flaw
A13: Confined Space | B13: Contractor | AT13: Workshop | AU13: Packaging | BA13: Inadequate Supervision
A14: LOTO
A15: Emergency Procedures

Sheet 08_Settings
B1: ⚙️ SYSTEM SETTINGS
B2: Central configuration — edit the blue cells. KPIs & the Executive Dashboard read these automatically.
B4: ORGANISATION
B5: Company Name | C5: RCPL — Campa Cola
B6: Plant / Site | C6: Manufacturing Plant 1
B7: Location | C7: India
B8: Reporting Year | C8: 2026
B10: EHS CALCULATION PARAMETERS
B11: Financial Year Start Month (1-12) | C11: 4 | D11: e.g. 4 = April
B12: Total Man-Hours Worked (annual) | C12: 1000000 | D12: Avg employees × hours worked
B13: TRIR Multiplier | C13: 200000 | D13: OSHA standard = 200,000
B14: LTIFR Multiplier | C14: 1000000 | D14: Per million man-hours
B16: TARGETS / RAG THRESHOLDS
B17: Observation Closure Target % | C17: 0.9 | D17: Green if ≥ target
B18: Training Compliance Target % | C18: 0.95
B19: Corrective Action Closure Target % | C19: 0.9
B20: TRIR Target (max acceptable) | C20: 1 | D20: Green if actual ≤ target
B21: RAG Amber band (% of target) | C21: 0.8 | D21: Below this vs target = Red

Sheet 09_Help
B1: ❓ HELP & USER GUIDE
B3: Enterprise Integrated EHS Management System
B4: Purpose | C4: Single-workbook EHS system: 24 data registers, per-register dashboards, and one Executive Dashboard with corporate KPIs.
B5: How to enter data
B6: Registers | C6: Open any register (colored tabs). Fill the 🔵 blue INPUT columns only. ⚫ Gray AUTO columns (S.No, Month, Week, Quarter, FY, Ageing, %) calculate themselves.
B7: Dropdowns | C7: All dropdowns are driven by 01_Master_Data. To add a Department, Location, etc., add it once there and every register updates automatically.
B8: Scalability | C8: Each register + dashboard supports up to ~500 records. Just keep typing below the sample rows — dashboards expand automatically.
B9: Dashboards
B10: Per-register | C10: Each "Dashboard – …" tab auto-summarises its register (KPI cards, trends, breakdowns, charts). No manual refresh needed.
B11: Executive | C11: 06_Executive_Dashboard aggregates ALL registers: TRIR, LTIFR, Incident Pyramid, Leading vs Lagging indicators, and a RAG compliance scorecard.
B12: Key formulas & settings
B13: TRIR | C13: =Recordable Cases × TRIR Multiplier ÷ Man-Hours. Recordable = Medical Treatment + Restricted Work + Lost Time Injury + Fatality.
B14: LTIFR | C14: =(Lost Time Injuries + Fatalities) × LTIFR Multiplier ÷ Man-Hours.
B15: Settings | C15: 08_Settings holds Man-Hours, multipliers, FY start month, and RAG targets. Edit the blue cells to match your plant.
B16: RAG logic | C16: 🟢 Green = meets target · 🟡 Amber = within the amber band · 🔴 Red = below. Bands are set in 08_Settings.
B17: Maintenance tips
B18: Recalculate | C18: Press F9 (or enable automatic calculation) if figures look stale. The file is set to full-recalculate on open.
B19: Backup | C19: Save a dated copy monthly. Never delete the 01_Master_Data or 08_Settings sheets — dropdowns and KPIs depend on them.
B20: Extending | C20: New registers follow the same pattern: register sheet + matching "Dashboard – …" sheet, lists in 01_Master_Data, KPIs wired to the Executive Dashboard.

Sheet Toolbox Talks
A1: 🗣️ TOOLBOX TALKS — DATA ENTRY
A2: 🔵 Blue = User Input | ⚫ Gray = Auto-Calculated | Use dropdowns where available
A3: IDENTIFICATION | E3: CONTENT | F3: ORGANIZATIONAL | H3: PEOPLE | I3: ATTENDANCE | L3: TIMING | M3: CLASSIFICATION | N3: FOLLOW-UP | O3: QUALITY
A4: S.No | B4: Ref No. | C4: Date | D4: Month | E4: Topic | F4: Department | G4: Location | H4: Conducted By | I4: Target Attendees | J4: Actual Attendees | K4: Attendance % | L4: Duration (min) | M4: Safety Category | N4: Action Required | O4: Effectiveness
A5: ⚙️ AUTO | B5: ✏️ INPUT | C5: ✏️ INPUT | D5: ⚙️ AUTO | E5: ✏️ INPUT | F5: ✏️ INPUT | G5: ✏️ INPUT | H5: ✏️ INPUT | I5: ✏️ INPUT | J5: ✏️ INPUT | K5: ⚙️ AUTO | L5: ✏️ INPUT | M5: ✏️ INPUT | N5: ✏️ INPUT | O5: ✏️ INPUT
A6: 1 | B6: TBT-001 | C6: 46330 | D6: =IF(C6="","",TEXT(C6,"MMM")) | E6: PPE Usage | F6: Safety | G6: Workshop | H6: Maria Garcia | I6: 12 | J6: 8 | K6: =IF(I6=0,0,J6/I6) | L6: 27 | M6: HIRA | N6: No | O6: Good
A7: 2 | B7: TBT-002 | C7: 46025 | D7: =IF(C7="","",TEXT(C7,"MMM")) | E7: Manual Handling | F7: Construction | G7: Plant A | H7: Tom Brown | I7: 14 | J7: 25 | K7: =IF(I7=0,0,J7/I7) | L7: 27 | M7: PPE | N7: Yes | O7: Needs Improvement
A8: 3 | B8: TBT-003 | C8: 46304 | D8: =IF(C8="","",TEXT(C8,"MMM")) | E8: PPE Usage | F8: Engineering | G8: Office | H8: Fatima Al-Said | I8: 16 | J8: 9 | K8: =IF(I8=0,0,J8/I8) | L8: 16 | M8: Emergency | N8: Yes | O8: Good
A9: 4 | B9: TBT-004 | C9: 46207 | D9: =IF(C9="","",TEXT(C9,"MMM")) | E9: Chemical Safety | F9: Logistics | G9: Field Site | H9: Ahmed Khan | I9: 22 | J9: 22 | K9: =IF(I9=0,0,J9/I9) | L9: 13 | M9: PPE | N9: Yes | O9: Excellent
A10: 5 | B10: TBT-005 | C10: 46346 | D10: =IF(C10="","",TEXT(C10,"MMM")) | E10: Chemical Safety | F10: Contractor | G10: Workshop | H10: Sarah Wilson | I10: 9 | J10: 12 | K10: =IF(I10=0,0,J10/I10) | L10: 19 | M10: HIRA | N10: Yes | O10: Good
A11: 6 | B11: TBT-006 | C11: 46212 | D11: =IF(C11="","",TEXT(C11,"MMM")) | E11: Heat Stress | F11: Logistics | G11: Warehouse | H11: Fatima Al-Said | I11: 19 | J11: 11 | K11: =IF(I11=0,0,J11/I11) | L11: 18 | M11: HIRA | N11: Yes | O11: Average
A12: 7 | B12: TBT-007 | C12: 46096 | D12: =IF(C12="","",TEXT(C12,"MMM")) | E12: Housekeeping | F12: Safety | G12: Workshop | H12: Fatima Al-Said | I12: 9 | J12: 12 | K12: =IF(I12=0,0,J12/I12) | L12: 11 | M12: Emergency | N12: No | O12: Excellent
A13: 8 | B13: TBT-008 | C13: 46060 | D13: =IF(C13="","",TEXT(C13,"MMM")) | E13: Confined Space | F13: Logistics | G13: Workshop | H13: Priya Sharma | I13: 20 | J13: 25 | K13: =IF(I13=0,0,J13/I13) | L13: 24 | M13: Training | N13: No | O13: Average
A14: 9 | B14: TBT-009 | C14: 46136 | D14: =IF(C14="","",TEXT(C14,"MMM")) | E14: Slip Trip Fall | F14: Projects | G14: Field Site | H14: Lisa Park | I14: 21 | J14: 23 | K14: =IF(I14=0,0,J14/I14) | L14: 22 | M14: Emergency | N14: Yes | O14: Average
A15: 10 | B15: TBT-010 | C15: 46281 | D15: =IF(C15="","",TEXT(C15,"MMM")) | E15: Fire Safety | F15: Operations | G15: Plant B | H15: Raj Patel | I15: 13 | J15: 18 | K15: =IF(I15=0,0,J15/I15) | L15: 29 | M15: HIRA | N15: No | O15: Needs Improvement
A16: 11 | B16: TBT-011 | C16: 46310 | D16: =IF(C16="","",TEXT(C16,"MMM")) | E16: Slip Trip Fall | F16: Safety | G16: Plant A | H16: Sarah Wilson | I16: 25 | J16: 13 | K16: =IF(I16=0,0,J16/I16) | L16: 30 | M16: Emergency | N16: Yes | O16: Excellent
A17: 12 | B17: TBT-012 | C17: 46209 | D17: =IF(C17="","",TEXT(C17,"MMM")) | E17: Heat Stress | F17: Operations | G17: Field Site | H17: Tom Brown | I17: 13 | J17: 21 | K17: =IF(I17=0,0,J17/I17) | L17: 13 | M17: General | N17: Yes | O17: Average
... A25: 20 | B25: TBT-020 | C25: 46130 | D25: =IF(C25="","",TEXT(C25,"MMM")) | E25: Heat Stress | F25: Engineering | G25: Office | H25: Raj Patel | I25: 16 | J25: 19 | K25: =IF(I25=0,0,J25/I25) | L25: 17 | M25: HIRA | N25: No | O25: Good
A26: =IF($B26="","",ROW()-5) | D26: =IF($B26="","",IF(C26="","",TEXT(C26,"MMM"))) | K26: =IF($B26="","",IF(I26=0,0,J26/I26))
A27: =IF($B27="","",ROW()-5) | D27: =IF($B27="","",IF(C27="","",TEXT(C27,"MMM"))) | K27: =IF($B27="","",IF(I27=0,0,J27/I27))
A28: =IF($B28="","",ROW()-5) | D28: =IF($B28="","",IF(C28="","",TEXT(C28,"MMM"))) | K28: =IF($B28="","",IF(I28=0,0,J28/I28))
A29: =IF($B29="","",ROW()-5) | D29: =IF($B29="","",IF(C29="","",TEXT(C29,"MMM"))) | K29: =IF($B29="","",IF(I29=0,0,J29/I29))
A30: =IF($B30="","",ROW()-5) | D30: =IF($B30="","",IF(C30="","",TEXT(C30,"MMM"))) | K30: =IF($B30="","",IF(I30=0,0,J30/I30))
A31: =IF($B31="","",ROW()-5) | D31: =IF($B31="","",IF(C31="","",TEXT(C31,"MMM"))) | K31: =IF($B31="","",IF(I31=0,0,J31/I31))
A32: =IF($B32="","",ROW()-5) | D32: =IF($B32="","",IF(C32="","",TEXT(C32,"MMM"))) | K32: =IF($B32="","",IF(I32=0,0,J32/I32))
A33: =IF($B33="","",ROW()-5) | D33: =IF($B33="","",IF(C33="","",TEXT(C33,"MMM"))) | K33: =IF($B33="","",IF(I33=0,0,J33/I33))
A34: =IF($B34="","",ROW()-5) | D34: =IF($B34="","",IF(C34="","",TEXT(C34,"MMM"))) | K34: =IF($B34="","",IF(I34=0,0,J34/I34))
A35: =IF($B35="","",ROW()-5) | D35: =IF($B35="","",IF(C35="","",TEXT(C35,"MMM"))) | K35: =IF($B35="","",IF(I35=0,0,J35/I35))
A36: =IF($B36="","",ROW()-5) | D36: =IF($B36="","",IF(C36="","",TEXT(C36,"MMM"))) | K36: =IF($B36="","",IF(I36=0,0,J36/I36))
A37: =IF($B37="","",ROW()-5) | D37: =IF($B37="","",IF(C37="","",TEXT(C37,"MMM"))) | K37: =IF($B37="","",IF(I37=0,0,J37/I37))
... A506: =IF($B506="","",ROW()-5) | D506: =IF($B506="","",IF(C506="","",TEXT(C506,"MMM"))) | K506: =IF($B506="","",IF(I506=0,0,J506/I506))

Sheet JSA Risk Assessment
A1: 📝 JSA / RISK ASSESSMENT — DATA ENTRY
A2: 🔵 Blue = User Input | ⚫ Gray = Auto-Calculated | Use dropdowns where available
A3: IDENTIFICATION | E3: ASSESSMENT | F3: ORGANIZATIONAL | H3: PEOPLE | J3: RISK | L3: CLASSIFICATION | M3: STATUS | N3: COMPLIANCE
A4: S.No | B4: JSA No. | C4: Date | D4: Month | E4: Task/Activity | F4: Department | G4: Location | H4: Assessed By | I4: Approved By | J4: Risk Level | K4: Hazards Identified | L4: Assessment Type | M4: Approval Status | N4: Controls Implemented | O4: Compliance
A5: ⚙️ AUTO | B5: ✏️ INPUT | C5: ✏️ INPUT | D5: ⚙️ AUTO | E5: ✏️ INPUT | F5: ✏️ INPUT | G5: ✏️ INPUT | H5: ✏️ INPUT | I5: ✏️ INPUT | J5: ✏️ INPUT | K5: ✏️ INPUT | L5: ✏️ INPUT | M5: ✏️ INPUT | N5: ✏️ INPUT | O5: ⚙️ AUTO
A6: 1 | B6: JSA-001 | C6: 46043 | D6: =IF(C6="","",TEXT(C6,"MMM")) | E6: Hot Tapping | F6: Operations | G6: Plant B | H6: Maria Garcia | I6: Raj Patel | J6: Low | K6: 10 | L6: HAZOP | M6: Approved | N6: No | O6: =IF(N6="Yes",IF(M6="Approved","✅ Compliant","⚠️ Pending"),"❌ Non-Compliant")
A7: 2 | B7: JSA-002 | C7: 46028 | D7: =IF(C7="","",TEXT(C7,"MMM")) | E7: Tank Cleaning | F7: Operations | G7: Office | H7: John Smith | I7: Priya Sharma | J7: Medium | K7: 9 | L7: Bow Tie | M7: Revision Required | N7: Yes | O7: =IF(N7="Yes",IF(M7="Approved","✅ Compliant","⚠️ Pending"),"❌ Non-Compliant")
A8: 3 | B8: JSA-003 | C8: 46122 | D8: =IF(C8="","",TEXT(C8,"MMM")) | E8: Excavation Work | F8: Operations | G8: Plant A | H8: Fatima Al-Said | I8: Ahmed Khan | J8: High | K8: 12 | L8: HAZOP | M8: Approved | N8: Yes | O8: =IF(N8="Yes",IF(M8="Approved","✅ Compliant","⚠️ Pending"),"❌ Non-Compliant")
A9: 4 | B9: JSA-004 | C9: 46268 | D9: =IF(C9="","",TEXT(C9,"MMM")) | E9: Scaffold Erection | F9: Maintenance | G9: Plant B | H9: Maria Garcia | I9: David Chen | J9: High | K9: 12 | L9: Task RA | M9: Approved | N9: Yes | O9: =IF(N9="Yes",IF(M9="Approved","✅ Compliant","⚠️ Pending"),"❌ Non-Compliant")
A10: 5 | B10: JSA-005 | C10: 46225 | D10: =IF(C10="","",TEXT(C10,"MMM")) | E10: Cable Pulling | F10: Contractor | G10: Control Room | H10: John Smith | I10: Maria Garcia | J10: Medium | K10: 6 | L10: JSA | M10: Revision Required | N10: Yes | O10: =IF(N10="Yes",IF(M10="Approved","✅ Compliant","⚠️ Pending"),"❌ Non-Compliant")
A11: 6 | B11: JSA-006 | C11: 46347 | D11: =IF(C11="","",TEXT(C11,"MMM")) | E11: Electrical Work | F11: Admin | G11: Control Room | H11: Sarah Wilson | I11: Ahmed Khan | J11: Low | K11: 12 | L11: What-If | M11: Approved | N11: Yes | O11: =IF(N11="Yes",IF(M11="Approved","✅ Compliant","⚠️ Pending"),"❌ Non-Compliant")
A12: 7 | B12: JSA-007 | C12: 46272 | D12: =IF(C12="","",TEXT(C12,"MMM")) | E12: Hot Tapping | F12: Safety | G12: Warehouse | H12: Fatima Al-Said | I12: Sarah Wilson | J12: Medium | K12: 8 | L12: JSA | M12: Approved | N12: No | O12: =IF(N12="Yes",IF(M12="Approved","✅ Compliant","⚠️ Pending"),"❌ Non-Compliant")
A13: 8 | B13: JSA-008 | C13: 46288 | D13: =IF(C13="","",TEXT(C13,"MMM")) | E13: Electrical Work | F13: Contractor | G13: Plant A | H13: Tom Brown | I13: John Smith | J13: High | K13: 5 | L13: JSA | M13: Approved | N13: Yes | O13: =IF(N13="Yes",IF(M13="Approved","✅ Compliant","⚠️ Pending"),"❌ Non-Compliant")
A14: 9 | B14: JSA-009 | C14: 46374 | D14: =IF(C14="","",TEXT(C14,"MMM")) | E14: Scaffold Erection | F14: Safety | G14: Field Site | H14: Lisa Park | I14: Maria Garcia | J14: Medium | K14: 6 | L14: Bow Tie | M14: Pending Review | N14: No | O14: =IF(N14="Yes",IF(M14="Approved","✅ Compliant","⚠️ Pending"),"❌ Non-Compliant")
A15: 10 | B15: JSA-010 | C15: 46170 | D15: =IF(C15="","",TEXT(C15,"MMM")) | E15: Welding Operation | F15: Maintenance | G15: Office | H15: John Smith | I15: Ahmed Khan | J15: High | K15: 8 | L15: Task RA | M15: Pending Review | N15: Yes | O15: =IF(N15="Yes",IF(M15="Approved","✅ Compliant","⚠️ Pending"),"❌ Non-Compliant")
A16: 11 | B16: JSA-011 | C16: 46371 | D16: =IF(C16="","",TEXT(C16,"MMM")) | E16: Hot Tapping | F16: Quality | G16: Plant A | H16: Sarah Wilson | I16: Sarah Wilson | J16: Medium | K16: 11 | L16: HIRA | M16: Pending Review | N16: Yes | O16: =IF(N16="Yes",IF(M16="Approved","✅ Compliant","⚠️ Pending"),"❌ Non-Compliant")
A17: 12 | B17: JSA-012 | C17: 46208 | D17: =IF(C17="","",TEXT(C17,"MMM")) | E17: Welding Operation | F17: Safety | G17: Control Room | H17: Ahmed Khan | I17: Fatima Al-Said | J17: Medium | K17: 6 | L17: Bow Tie | M17: Approved | N17: Yes | O17: =IF(N17="Yes",IF(M17="Approved","✅ Compliant","⚠️ Pending"),"❌ Non-Compliant")
... A23: 18 | B23: JSA-018 | C23: 46045 | D23: =IF(C23="","",TEXT(C23,"MMM")) | E23: Tank Cleaning | F23: Operations | G23: Workshop | H23: Fatima Al-Said | I23: David Chen | J23: High | K23: 8 | L23: What-If | M23: Pending Review | N23: Yes | O23: =IF(N23="Yes",IF(M23="Approved","✅ Compliant","⚠️ Pending"),"❌ Non-Compliant")
A24: =IF($B24="","",ROW()-5) | D24: =IF($B24="","",IF(C24="","",TEXT(C24,"MMM"))) | O24: =IF($B24="","",IF(N24="Yes",IF(M24="Approved","✅ Compliant","⚠️ Pending"),"❌ Non-Compliant"))
A25: =IF($B25="","",ROW()-5) | D25: =IF($B25="","",IF(C25="","",TEXT(C25,"MMM"))) | O25: =IF($B25="","",IF(N25="Yes",IF(M25="Approved","✅ Compliant","⚠️ Pending"),"❌ Non-Compliant"))
A26: =IF($B26="","",ROW()-5) | D26: =IF($B26="","",IF(C26="","",TEXT(C26,"MMM"))) | O26: =IF($B26="","",IF(N26="Yes",IF(M26="Approved","✅ Compliant","⚠️ Pending"),"❌ Non-Compliant"))
A27: =IF($B27="","",ROW()-5) | D27: =IF($B27="","",IF(C27="","",TEXT(C27,"MMM"))) | O27: =IF($B27="","",IF(N27="Yes",IF(M27="Approved","✅ Compliant","⚠️ Pending"),"❌ Non-Compliant"))
A28: =IF($B28="","",ROW()-5) | D28: =IF($B28="","",IF(C28="","",TEXT(C28,"MMM"))) | O28: =IF($B28="","",IF(N28="Yes",IF(M28="Approved","✅ Compliant","⚠️ Pending"),"❌ Non-Compliant"))
A29: =IF($B29="","",ROW()-5) | D29: =IF($B29="","",IF(C29="","",TEXT(C29,"MMM"))) | O29: =IF($B29="","",IF(N29="Yes",IF(M29="Approved","✅ Compliant","⚠️ Pending"),"❌ Non-Compliant"))
A30: =IF($B30="","",ROW()-5) | D30: =IF($B30="","",IF(C30="","",TEXT(C30,"MMM"))) | O30: =IF($B30="","",IF(N30="Yes",IF(M30="Approved","✅ Compliant","⚠️ Pending"),"❌ Non-Compliant"))
A31: =IF($B31="","",ROW()-5) | D31: =IF($B31="","",IF(C31="","",TEXT(C31,"MMM"))) | O31: =IF($B31="","",IF(N31="Yes",IF(M31="Approved","✅ Compliant","⚠️ Pending"),"❌ Non-Compliant"))
A32: =IF($B32="","",ROW()-5) | D32: =IF($B32="","",IF(C32="","",TEXT(C32,"MMM"))) | O32: =IF($B32="","",IF(N32="Yes",IF(M32="Approved","✅ Compliant","⚠️ Pending"),"❌ Non-Compliant"))
A33: =IF($B33="","",ROW()-5) | D33: =IF($B33="","",IF(C33="","",TEXT(C33,"MMM"))) | O33: =IF($B33="","",IF(N33="Yes",IF(M33="Approved","✅ Compliant","⚠️ Pending"),"❌ Non-Compliant"))
A34: =IF($B34="","",ROW()-5) | D34: =IF($B34="","",IF(C34="","",TEXT(C34,"MMM"))) | O34: =IF($B34="","",IF(N34="Yes",IF(M34="Approved","✅ Compliant","⚠️ Pending"),"❌ Non-Compliant"))
A35: =IF($B35="","",ROW()-5) | D35: =IF($B35="","",IF(C35="","",TEXT(C35,"MMM"))) | O35: =IF($B35="","",IF(N35="Yes",IF(M35="Approved","✅ Compliant","⚠️ Pending"),"❌ Non-Compliant"))
... A506: =IF($B506="","",ROW()-5) | D506: =IF($B506="","",IF(C506="","",TEXT(C506,"MMM"))) | O506: =IF($B506="","",IF(N506="Yes",IF(M506="Approved","✅ Compliant","⚠️ Pending"),"❌ Non-Compliant"))

Sheet Training
A1: 🎓 TRAINING — DATA ENTRY
A2: 🔵 Blue = User Input | ⚫ Gray = Auto-Calculated | Use dropdowns where available
A3: IDENTIFICATION | E3: CONTENT | F3: CLASSIFICATION | G3: ORGANIZATIONAL | H3: PEOPLE | I3: CLASSIFICATION | J3: ATTENDANCE | M3: TIMING | N3: STATUS | O3: QUALITY | P3: COMPLIANCE
A4: S.No | B4: Training ID | C4: Date | D4: Month | E4: Course Name | F4: Training Type | G4: Department | H4: Trainer | I4: Mode | J4: Target Attendees | K4: Actual Attendees | L4: Attendance % | M4: Duration (hrs) | N4: Status | O4: Assessment Result | P4: Certificate Issued
A5: ⚙️ AUTO | B5: ✏️ INPUT | C5: ✏️ INPUT | D5: ⚙️ AUTO | E5: ✏️ INPUT | F5: ✏️ INPUT | G5: ✏️ INPUT | H5: ✏️ INPUT | I5: ✏️ INPUT | J5: ✏️ INPUT | K5: ✏️ INPUT | L5: ⚙️ AUTO | M5: ✏️ INPUT | N5: ✏️ INPUT | O5: ✏️ INPUT | P5: ✏️ INPUT
A6: 1 | B6: TRN-001 | C6: 46366 | D6: =IF(C6="","",TEXT(C6,"MMM")) | E6: Environmental | F6: Advanced | G6: Quality | H6: Fatima Al-Said | I6: On-the-Job | J6: 19 | K6: 25 | L6: =IF(J6=0,0,K6/J6) | M6: 4 | N6: Completed | O6: Fail | P6: No
A7: 2 | B7: TRN-002 | C7: 46225 | D7: =IF(C7="","",TEXT(C7,"MMM")) | E7: Confined Space | F7: Refresher | G7: Contractor | H7: Lisa Park | I7: Online | J7: 22 | K7: 25 | L7: =IF(J7=0,0,K7/J7) | M7: 2 | N7: Completed | O7: Pass | P7: Yes
A8: 3 | B8: TRN-003 | C8: 46229 | D8: =IF(C8="","",TEXT(C8,"MMM")) | E8: Incident Investigation | F8: Awareness | G8: Logistics | H8: Priya Sharma | I8: On-the-Job | J8: 24 | K8: 29 | L8: =IF(J8=0,0,K8/J8) | M8: 4 | N8: Scheduled | O8: Fail | P8: No
A9: 4 | B9: TRN-004 | C9: 46103 | D9: =IF(C9="","",TEXT(C9,"MMM")) | E9: Fire Fighting | F9: Advanced | G9: Projects | H9: Lisa Park | I9: Online | J9: 12 | K9: 15 | L9: =IF(J9=0,0,K9/J9) | M9: 40 | N9: Completed | O9: Pass | P9: Yes
A10: 5 | B10: TRN-005 | C10: 46082 | D10: =IF(C10="","",TEXT(C10,"MMM")) | E10: First Aid | F10: Refresher | G10: Admin | H10: Lisa Park | I10: Internal | J10: 24 | K10: 21 | L10: =IF(J10=0,0,K10/J10) | M10: 40 | N10: Scheduled | O10: Pass | P10: No
A11: 6 | B11: TRN-006 | C11: 46369 | D11: =IF(C11="","",TEXT(C11,"MMM")) | E11: Crane Safety | F11: Certification | G11: Construction | H11: Raj Patel | I11: Internal | J11: 13 | K11: 21 | L11: =IF(J11=0,0,K11/J11) | M11: 4 | N11: Completed | O11: N/A | P11: Yes
A12: 7 | B12: TRN-007 | C12: 46040 | D12: =IF(C12="","",TEXT(C12,"MMM")) | E12: Defensive Driving | F12: Induction | G12: Admin | H12: Raj Patel | I12: On-the-Job | J12: 26 | K12: 25 | L12: =IF(J12=0,0,K12/J12) | M12: 24 | N12: Completed | O12: Fail | P12: No
A13: 8 | B13: TRN-008 | C13: 46373 | D13: =IF(C13="","",TEXT(C13,"MMM")) | E13: Scaffold Safety | F13: Awareness | G13: Admin | H13: Raj Patel | I13: On-the-Job | J13: 24 | K13: 16 | L13: =IF(J13=0,0,K13/J13) | M13: 4 | N13: Completed | O13: N/A | P13: Yes
A14: 9 | B14: TRN-009 | C14: 46334 | D14: =IF(C14="","",TEXT(C14,"MMM")) | E14: PTW Training | F14: Certification | G14: Maintenance | H14: John Smith | I14: External | J14: 18 | K14: 18 | L14: =IF(J14=0,0,K14/J14) | M14: 8 | N14: Scheduled | O14: Pass | P14: Yes
A15: 10 | B15: TRN-010 | C15: 46089 | D15: =IF(C15="","",TEXT(C15,"MMM")) | E15: Scaffold Safety | F15: Competency | G15: Engineering | H15: Maria Garcia | I15: Internal | J15: 23 | K15: 21 | L15: =IF(J15=0,0,K15/J15) | M15: 8 | N15: Scheduled | O15: Fail | P15: Yes
A16: 11 | B16: TRN-011 | C16: 46029 | D16: =IF(C16="","",TEXT(C16,"MMM")) | E16: Scaffold Safety | F16: Certification | G16: Contractor | H16: Ahmed Khan | I16: On-the-Job | J16: 25 | K16: 8 | L16: =IF(J16=0,0,K16/J16) | M16: 8 | N16: Completed | O16: Fail | P16: Yes
A17: 12 | B17: TRN-012 | C17: 46289 | D17: =IF(C17="","",TEXT(C17,"MMM")) | E17: Confined Space | F17: Awareness | G17: Contractor | H17: Maria Garcia | I17: On-the-Job | J17: 17 | K17: 16 | L17: =IF(J17=0,0,K17/J17) | M17: 16 | N17: In Progress | O17: Pass | P17: Yes
... A25: 20 | B25: TRN-020 | C25: 46176 | D25: =IF(C25="","",TEXT(C25,"MMM")) | E25: Environmental | F25: Competency | G25: Logistics | H25: Ahmed Khan | I25: On-the-Job | J25: 25 | K25: 11 | L25: =IF(J25=0,0,K25/J25) | M25: 16 | N25: Completed | O25: Fail | P25: No
A26: =IF($B26="","",ROW()-5) | D26: =IF($B26="","",IF(C26="","",TEXT(C26,"MMM"))) | L26: =IF($B26="","",IF(J26=0,0,K26/J26))
A27: =IF($B27="","",ROW()-5) | D27: =IF($B27="","",IF(C27="","",TEXT(C27,"MMM"))) | L27: =IF($B27="","",IF(J27=0,0,K27/J27))
A28: =IF($B28="","",ROW()-5) | D28: =IF($B28="","",IF(C28="","",TEXT(C28,"MMM"))) | L28: =IF($B28="","",IF(J28=0,0,K28/J28))
A29: =IF($B29="","",ROW()-5) | D29: =IF($B29="","",IF(C29="","",TEXT(C29,"MMM"))) | L29: =IF($B29="","",IF(J29=0,0,K29/J29))
A30: =IF($B30="","",ROW()-5) | D30: =IF($B30="","",IF(C30="","",TEXT(C30,"MMM"))) | L30: =IF($B30="","",IF(J30=0,0,K30/J30))
A31: =IF($B31="","",ROW()-5) | D31: =IF($B31="","",IF(C31="","",TEXT(C31,"MMM"))) | L31: =IF($B31="","",IF(J31=0,0,K31/J31))
A32: =IF($B32="","",ROW()-5) | D32: =IF($B32="","",IF(C32="","",TEXT(C32,"MMM"))) | L32: =IF($B32="","",IF(J32=0,0,K32/J32))
A33: =IF($B33="","",ROW()-5) | D33: =IF($B33="","",IF(C33="","",TEXT(C33,"MMM"))) | L33: =IF($B33="","",IF(J33=0,0,K33/J33))
A34: =IF($B34="","",ROW()-5) | D34: =IF($B34="","",IF(C34="","",TEXT(C34,"MMM"))) | L34: =IF($B34="","",IF(J34=0,0,K34/J34))
A35: =IF($B35="","",ROW()-5) | D35: =IF($B35="","",IF(C35="","",TEXT(C35,"MMM"))) | L35: =IF($B35="","",IF(J35=0,0,K35/J35))
A36: =IF($B36="","",ROW()-5) | D36: =IF($B36="","",IF(C36="","",TEXT(C36,"MMM"))) | L36: =IF($B36="","",IF(J36=0,0,K36/J36))
A37: =IF($B37="","",ROW()-5) | D37: =IF($B37="","",IF(C37="","",TEXT(C37,"MMM"))) | L37: =IF($B37="","",IF(J37=0,0,K37/J37))
... A506: =IF($B506="","",ROW()-5) | D506: =IF($B506="","",IF(C506="","",TEXT(C506,"MMM"))) | L506: =IF($B506="","",IF(J506=0,0,K506/J506))

Sheet HSE Observations
A1: 👁️ HSE OBSERVATIONS — DATA ENTRY
A2: 🔵 Blue = User Input | ⚫ Gray = Auto-Calculated | Use dropdowns where available
A3: IDENTIFICATION | E3: CLASSIFICATION | F3: CONTENT | G3: ORGANIZATIONAL | I3: PEOPLE | K3: CLASSIFICATION | L3: RISK | M3: STATUS | N3: FOLLOW-UP
A4: S.No | B4: Obs No. | C4: Date | D4: Month | E4: Observation Type | F4: Description | G4: Department | H4: Location | I4: Observed By | J4: Responsible Person | K4: Category | L4: Risk Level | M4: Status | N4: Action Taken | O4: Due Date
A5: ⚙️ AUTO | B5: ✏️ INPUT | C5: ✏️ INPUT | D5: ⚙️ AUTO | E5: ✏️ INPUT | F5: ✏️ INPUT | G5: ✏️ INPUT | H5: ✏️ INPUT | I5: ✏️ INPUT | J5: ✏️ INPUT | K5: ✏️ INPUT | L5: ✏️ INPUT | M5: ✏️ INPUT | N5: ✏️ INPUT | O5: ✏️ INPUT
A6: 1 | B6: OBS-001 | C6: 46095 | D6: =IF(C6="","",TEXT(C6,"MMM")) | E6: Unsafe Act | F6: Unsafe Act - Improper Lifting | G6: Contractor | H6: Tank Farm | I6: Priya Sharma | J6: David Chen | K6: Environment | L6: Low | M6: Overdue | N6: Fix condition | O6: 46083
A7: 2 | B7: OBS-002 | C7: 46137 | D7: =IF(C7="","",TEXT(C7,"MMM")) | E7: Unsafe Condition | F7: Unsafe Condition - Poor Lighting | G7: Logistics | H7: Plant A | I7: Priya Sharma | J7: Fatima Al-Said | K7: General | L7: Medium | M7: In Progress | N7: Fix condition | O7: 46208
A8: 3 | B8: OBS-003 | C8: 46365 | D8: =IF(C8="","",TEXT(C8,"MMM")) | E8: Near Miss | F8: Unsafe Act - No PPE | G8: Projects | H8: Workshop | I8: Sarah Wilson | J8: Maria Garcia | K8: Fire Safety | L8: Medium | M8: Pending | N8: Recognize employee | O8: 46399
A9: 4 | B9: OBS-004 | C9: 46372 | D9: =IF(C9="","",TEXT(C9,"MMM")) | E9: Unsafe Condition | F9: Unsafe Act - No PPE | G9: Maintenance | H9: Field Site | I9: Maria Garcia | J9: David Chen | K9: Fire Safety | L9: High | M9: Overdue | N9: Recognize employee | O9: 46300
A10: 5 | B10: OBS-005 | C10: 46227 | D10: =IF(C10="","",TEXT(C10,"MMM")) | E10: Near Miss | F10: Safe Behavior - Barricading | G10: Logistics | H10: Tank Farm | I10: John Smith | J10: John Smith | K10: PPE | L10: High | M10: Completed | N10: Retrain worker | O10: 46403
A11: 6 | B11: OBS-006 | C11: 46088 | D11: =IF(C11="","",TEXT(C11,"MMM")) | E11: Unsafe Act | F11: Near Miss - Falling Object | G11: Safety | H11: Field Site | I11: Sarah Wilson | J11: Maria Garcia | K11: PPE | L11: High | M11: Overdue | N11: Retrain worker | O11: 46385
A12: 7 | B12: OBS-007 | C12: 46144 | D12: =IF(C12="","",TEXT(C12,"MMM")) | E12: Safe Act | F12: Unsafe Act - Improper Lifting | G12: Engineering | H12: Tank Farm | I12: Sarah Wilson | J12: Ahmed Khan | K12: Ergonomics | L12: Medium | M12: Pending | N12: Install signage | O12: 46098
A13: 8 | B13: OBS-008 | C13: 46238 | D13: =IF(C13="","",TEXT(C13,"MMM")) | E13: Safe Act | F13: Unsafe Condition - Poor Lighting | G13: Admin | H13: Plant B | I13: Lisa Park | J13: Ahmed Khan | K13: General | L13: High | M13: Overdue | O13: 46091
A14: 9 | B14: OBS-009 | C14: 46315 | D14: =IF(C14="","",TEXT(C14,"MMM")) | E14: Near Miss | F14: Positive - Good Housekeeping | G14: Projects | H14: Office | I14: Priya Sharma | J14: Priya Sharma | K14: PPE | L14: Low | M14: Pending | N14: Fix condition | O14: 46072
A15: 10 | B15: OBS-010 | C15: 46078 | D15: =IF(C15="","",TEXT(C15,"MMM")) | E15: Unsafe Act | F15: Positive - Good Housekeeping | G15: Safety | H15: Plant B | I15: Raj Patel | J15: Maria Garcia | K15: General | L15: Low | M15: Completed | N15: Retrain worker
A16: 11 | B16: OBS-011 | C16: 46257 | D16: =IF(C16="","",TEXT(C16,"MMM")) | E16: Near Miss | F16: Near Miss - Falling Object | G16: Safety | H16: Plant A | I16: Maria Garcia | J16: John Smith | K16: Fire Safety | L16: Medium | M16: Pending | O16: 46195
A17: 12 | B17: OBS-012 | C17: 46317 | D17: =IF(C17="","",TEXT(C17,"MMM")) | E17: Unsafe Act | F17: Unsafe Condition - Poor Lighting | G17: Maintenance | H17: Workshop | I17: Raj Patel | J17: John Smith | K17: Environment | L17: High | M17: Completed
A18: 13 | B18: OBS-013 | C18: 46162 | D18: =IF(C18="","",TEXT(C18,"MMM")) | E18: Near Miss | F18: Unsafe Act - Improper Lifting | G18: Admin | H18: Plant B | I18: Priya Sharma | J18: John Smith | K18: Fire Safety | L18: Medium | M18: Overdue | N18: Recognize employee | O18: 46263
A19: 14 | B19: OBS-014 | C19: 46036 | D19: =IF(C19="","",TEXT(C19,"MMM")) | E19: Safe Condition | F19: Unsafe Act - Improper Lifting | G19: Operations | H19: Plant B | I19: Maria Garcia | J19: Lisa Park | K19: Ergonomics | L19: High | M19: Overdue | N19: Recognize employee
A20: 15 | B20: OBS-015 | C20: 46097 | D20: =IF(C20="","",TEXT(C20,"MMM")) | E20: Near Miss | F20: Near Miss - Falling Object | G20: Safety | H20: Warehouse | I20: Lisa Park | J20: David Chen | K20: Fire Safety | L20: Medium | M20: Completed | N20: Install signage | O20: 46212
A21: 16 | B21: OBS-016 | C21: 46081 | D21: =IF(C21="","",TEXT(C21,"MMM")) | E21: Unsafe Act | F21: Safe Behavior - Barricading | G21: Quality | H21: Tank Farm | I21: John Smith | J21: David Chen | K21: Environment | L21: Low | M21: Completed | N21: Install signage
A22: 17 | B22: OBS-017 | C22: 46153 | D22: =IF(C22="","",TEXT(C22,"MMM")) | E22: Safe Act | F22: Unsafe Condition - Poor Lighting | G22: Projects | H22: Plant A | I22: Tom Brown | J22: Priya Sharma | K22: Housekeeping | L22: High | M22: In Progress | N22: Recognize employee | O22: 46276
A23: 18 | B23: OBS-018 | C23: 46029 | D23: =IF(C23="","",TEXT(C23,"MMM")) | E23: Safe Condition | F23: Unsafe Condition - Spill | G23: Safety | H23: Tank Farm | I23: Priya Sharma | J23: Sarah Wilson | K23: BBS | L23: Low | M23: In Progress | N23: Retrain worker | O23: 46060
A24: 19 | B24: OBS-019 | C24: 46061 | D24: =IF(C24="","",TEXT(C24,"MMM")) | E24: Safe Act | F24: Near Miss - Falling Object | G24: Maintenance | H24: Warehouse | I24: Priya Sharma | J24: John Smith | K24: Ergonomics | L24: Low | M24: Overdue | N24: Install signage | O24: 46263
A25: 20 | B25: OBS-020 | C25: 46270 | D25: =IF(C25="","",TEXT(C25,"MMM")) | E25: Unsafe Condition | F25: Positive - Good Housekeeping | G25: Contractor | H25: Warehouse | I25: Sarah Wilson | J25: John Smith | K25: Environment | L25: Medium | M25: Overdue | N25: Recognize employee
A26: =IF($B26="","",ROW()-5) | D26: =IF($B26="","",IF(C26="","",TEXT(C26,"MMM")))
A27: =IF($B27="","",ROW()-5) | D27: =IF($B27="","",IF(C27="","",TEXT(C27,"MMM")))
A28: =IF($B28="","",ROW()-5) | D28: =IF($B28="","",IF(C28="","",TEXT(C28,"MMM")))
A29: =IF($B29="","",ROW()-5) | D29: =IF($B29="","",IF(C29="","",TEXT(C29,"MMM")))
A30: =IF($B30="","",ROW()-5) | D30: =IF($B30="","",IF(C30="","",TEXT(C30,"MMM")))
A31: =IF($B31="","",ROW()-5) | D31: =IF($B31="","",IF(C31="","",TEXT(C31,"MMM")))
A32: =IF($B32="","",ROW()-5) | D32: =IF($B32="","",IF(C32="","",TEXT(C32,"MMM")))
A33: =IF($B33="","",ROW()-5) | D33: =IF($B33="","",IF(C33="","",TEXT(C33,"MMM")))
A34: =IF($B34="","",ROW()-5) | D34: =IF($B34="","",IF(C34="","",TEXT(C34,"MMM")))
A35: =IF($B35="","",ROW()-5) | D35: =IF($B35="","",IF(C35="","",TEXT(C35,"MMM")))
A36: =IF($B36="","",ROW()-5) | D36: =IF($B36="","",IF(C36="","",TEXT(C36,"MMM")))
A37: =IF($B37="","",ROW()-5) | D37: =IF($B37="","",IF(C37="","",TEXT(C37,"MMM")))
... A506: =IF($B506="","",ROW()-5) | D506: =IF($B506="","",IF(C506="","",TEXT(C506,"MMM")))

Sheet Workplace Inspections
A1: 🔍 WORKPLACE INSPECTIONS — DATA ENTRY
A2: 🔵 Blue = User Input | ⚫ Gray = Auto-Calculated | Use dropdowns where available
A3: IDENTIFICATION | E3: SCOPE | F3: ORGANIZATIONAL | H3: PEOPLE | I3: FINDINGS | L3: QUALITY | M3: STATUS | N3: FOLLOW-UP
A4: S.No | B4: Ref No. | C4: Date | D4: Month | E4: Inspection Area/Item | F4: Department | G4: Location | H4: Inspector | I4: Checkpoints Inspected | J4: Non-Conformances | K4: Critical Findings | L4: Overall Rating | M4: Status | N4: Corrective Action | O4: Due Date
A5: ⚙️ AUTO | B5: ✏️ INPUT | C5: ✏️ INPUT | D5: ⚙️ AUTO | E5: ✏️ INPUT | F5: ✏️ INPUT | G5: ✏️ INPUT | H5: ✏️ INPUT | I5: ✏️ INPUT | J5: ✏️ INPUT | K5: ✏️ INPUT | L5: ✏️ INPUT | M5: ✏️ INPUT | N5: ✏️ INPUT | O5: ✏️ INPUT
A6: 1 | B6: WPI-001 | C6: 46032 | D6: =IF(C6="","",TEXT(C6,"MMM")) | E6: Chemical Storage | F6: Contractor | G6: Tank Farm | H6: Raj Patel | I6: 19 | J6: 4 | K6: 3 | L6: Unsatisfactory | M6: Overdue | N6: Install guard | O6: 46235
A7: 2 | B7: WPI-002 | C7: 46135 | D7: =IF(C7="","",TEXT(C7,"MMM")) | E7: Emergency Exit | F7: Contractor | G7: Office | H7: Maria Garcia | I7: 18 | J7: 0 | K7: 2 | L7: Good | M7: Pending | N7: Clean area | O7: 46353
A8: 3 | B8: WPI-003 | C8: 46027 | D8: =IF(C8="","",TEXT(C8,"MMM")) | E8: Ventilation | F8: Contractor | G8: Control Room | H8: Sarah Wilson | I8: 19 | J8: 0 | K8: 3 | L8: Satisfactory | M8: In Progress | N8: Clean area | O8: 46106
A9: 4 | B9: WPI-004 | C9: 46153 | D9: =IF(C9="","",TEXT(C9,"MMM")) | E9: Lighting | F9: Quality | G9: Plant B | H9: Fatima Al-Said | I9: 17 | J9: 2 | K9: 3 | L9: Excellent | M9: Completed | N9: Install guard
A10: 5 | B10: WPI-005 | C10: 46348 | D10: =IF(C10="","",TEXT(C10,"MMM")) | E10: Chemical Storage | F10: Construction | G10: Plant B | H10: David Chen | I10: 8 | J10: 5 | K10: 0 | L10: Good | M10: In Progress | N10: Replace equipment | O10: 46041
A11: 6 | B11: WPI-006 | C11: 46154 | D11: =IF(C11="","",TEXT(C11,"MMM")) | E11: Electrical Panel | F11: Quality | G11: Warehouse | H11: Maria Garcia | I11: 18 | J11: 4 | K11: 1 | L11: Needs Improvement | M11: In Progress | O11: 46251
A12: 7 | B12: WPI-007 | C12: 46128 | D12: =IF(C12="","",TEXT(C12,"MMM")) | E12: Lighting | F12: Engineering | G12: Workshop | H12: Priya Sharma | I12: 13 | J12: 3 | K12: 2 | L12: Satisfactory | M12: Pending | N12: Replace equipment | O12: 46105
A13: 8 | B13: WPI-008 | C13: 46192 | D13: =IF(C13="","",TEXT(C13,"MMM")) | E13: Chemical Storage | F13: Quality | G13: Field Site | H13: Priya Sharma | I13: 14 | J13: 1 | K13: 3 | L13: Good | M13: Completed | N13: Fix issue | O13: 46208
A14: 9 | B14: WPI-009 | C14: 46366 | D14: =IF(C14="","",TEXT(C14,"MMM")) | E14: Fire Equipment | F14: Quality | G14: Field Site | H14: Ahmed Khan | I14: 6 | J14: 4 | K14: 3 | L14: Unsatisfactory | M14: In Progress | N14: Install guard | O14: 46146
A15: 10 | B15: WPI-010 | C15: 46304 | D15: =IF(C15="","",TEXT(C15,"MMM")) | E15: PPE Station | F15: Maintenance | G15: Plant A | H15: John Smith | I15: 19 | J15: 0 | K15: 2 | L15: Needs Improvement | M15: Completed | N15: Replace equipment | O15: 46222
A16: 11 | B16: WPI-011 | C16: 46107 | D16: =IF(C16="","",TEXT(C16,"MMM")) | E16: Ventilation | F16: Logistics | G16: Field Site | H16: Raj Patel | I16: 13 | J16: 3 | K16: 2 | L16: Unsatisfactory | M16: Completed | N16: Clean area | O16: 46120
A17: 12 | B17: WPI-012 | C17: 46350 | D17: =IF(C17="","",TEXT(C17,"MMM")) | E17: First Aid Kit | F17: Projects | G17: Control Room | H17: Sarah Wilson | I17: 17 | J17: 0 | K17: 2 | L17: Excellent | M17: Completed | N17: Clean area | O17: 46393
A18: 13 | B18: WPI-013 | C18: 46308 | D18: =IF(C18="","",TEXT(C18,"MMM")) | E18: Electrical Panel | F18: Maintenance | G18: Workshop | H18: Priya Sharma | I18: 5 | J18: 4 | K18: 2 | L18: Excellent | M18: In Progress | O18: 46273
A19: 14 | B19: WPI-014 | C19: 46340 | D19: =IF(C19="","",TEXT(C19,"MMM")) | E19: Housekeeping | F19: Engineering | G19: Plant A | H19: Ahmed Khan | I19: 14 | J19: 3 | K19: 0 | L19: Satisfactory | M19: In Progress | N19: Install guard
A20: 15 | B20: WPI-015 | C20: 46246 | D20: =IF(C20="","",TEXT(C20,"MMM")) | E20: Ventilation | F20: Quality | G20: Warehouse | H20: David Chen | I20: 8 | J20: 3 | K20: 3 | L20: Unsatisfactory | M20: Completed | N20: Replace equipment
A21: 16 | B21: WPI-016 | C21: 46242 | D21: =IF(C21="","",TEXT(C21,"MMM")) | E21: Electrical Panel | F21: Maintenance | G21: Control Room | H21: Tom Brown | I21: 16 | J21: 0 | K21: 3 | L21: Unsatisfactory | M21: In Progress | O21: 46265
A22: 17 | B22: WPI-017 | C22: 46133 | D22: =IF(C22="","",TEXT(C22,"MMM")) | E22: Lighting | F22: Operations | G22: Plant A | H22: Fatima Al-Said | I22: 12 | J22: 1 | K22: 1 | L22: Satisfactory | M22: Cancelled | N22: Fix issue | O22: 46134
A23: 18 | B23: WPI-018 | C23: 46296 | D23: =IF(C23="","",TEXT(C23,"MMM")) | E23: Chemical Storage | F23: Engineering | G23: Warehouse | H23: Tom Brown | I23: 13 | J23: 1 | K23: 0 | L23: Satisfactory | M23: In Progress | O23: 46148
A24: =IF($B24="","",ROW()-5) | D24: =IF($B24="","",IF(C24="","",TEXT(C24,"MMM")))
A25: =IF($B25="","",ROW()-5) | D25: =IF($B25="","",IF(C25="","",TEXT(C25,"MMM")))
A26: =IF($B26="","",ROW()-5) | D26: =IF($B26="","",IF(C26="","",TEXT(C26,"MMM")))
A27: =IF($B27="","",ROW()-5) | D27: =IF($B27="","",IF(C27="","",TEXT(C27,"MMM")))
A28: =IF($B28="","",ROW()-5) | D28: =IF($B28="","",IF(C28="","",TEXT(C28,"MMM")))
A29: =IF($B29="","",ROW()-5) | D29: =IF($B29="","",IF(C29="","",TEXT(C29,"MMM")))
A30: =IF($B30="","",ROW()-5) | D30: =IF($B30="","",IF(C30="","",TEXT(C30,"MMM")))
A31: =IF($B31="","",ROW()-5) | D31: =IF($B31="","",IF(C31="","",TEXT(C31,"MMM")))
A32: =IF($B32="","",ROW()-5) | D32: =IF($B32="","",IF(C32="","",TEXT(C32,"MMM")))
A33: =IF($B33="","",ROW()-5) | D33: =IF($B33="","",IF(C33="","",TEXT(C33,"MMM")))
A34: =IF($B34="","",ROW()-5) | D34: =IF($B34="","",IF(C34="","",TEXT(C34,"MMM")))
A35: =IF($B35="","",ROW()-5) | D35: =IF($B35="","",IF(C35="","",TEXT(C35,"MMM")))
... A506: =IF($B506="","",ROW()-5) | D506: =IF($B506="","",IF(C506="","",TEXT(C506,"MMM")))

Sheet Equipment Inspections
A1: 🔧 EQUIPMENT INSPECTIONS — DATA ENTRY
A2: 🔵 Blue = User Input | ⚫ Gray = Auto-Calculated | Use dropdowns where available
A3: IDENTIFICATION | E3: SCOPE | F3: ORGANIZATIONAL | H3: PEOPLE | I3: FINDINGS | L3: QUALITY | M3: STATUS | N3: FOLLOW-UP
A4: S.No | B4: Ref No. | C4: Date | D4: Month | E4: Inspection Area/Item | F4: Department | G4: Location | H4: Inspector | I4: Checkpoints Inspected | J4: Non-Conformances | K4: Critical Findings | L4: Overall Rating | M4: Status | N4: Corrective Action | O4: Due Date
A5: ⚙️ AUTO | B5: ✏️ INPUT | C5: ✏️ INPUT | D5: ⚙️ AUTO | E5: ✏️ INPUT | F5: ✏️ INPUT | G5: ✏️ INPUT | H5: ✏️ INPUT | I5: ✏️ INPUT | J5: ✏️ INPUT | K5: ✏️ INPUT | L5: ✏️ INPUT | M5: ✏️ INPUT | N5: ✏️ INPUT | O5: ✏️ INPUT
A6: 1 | B6: EQI-001 | C6: 46028 | D6: =IF(C6="","",TEXT(C6,"MMM")) | E6: Compressor | F6: Operations | G6: Warehouse | H6: David Chen | I6: 8 | J6: 5 | K6: 0 | L6: Good | M6: Pending | N6: Replace equipment | O6: 46091
A7: 2 | B7: EQI-002 | C7: 46132 | D7: =IF(C7="","",TEXT(C7,"MMM")) | E7: Crane | F7: Projects | G7: Field Site | H7: Priya Sharma | I7: 5 | J7: 0 | K7: 3 | L7: Good | M7: Pending | O7: 46246
A8: 3 | B8: EQI-003 | C8: 46193 | D8: =IF(C8="","",TEXT(C8,"MMM")) | E8: Scaffold | F8: Maintenance | G8: Warehouse | H8: John Smith | I8: 15 | J8: 3 | K8: 2 | L8: Good | M8: Cancelled | N8: Install guard | O8: 46387
A9: 4 | B9: EQI-004 | C9: 46351 | D9: =IF(C9="","",TEXT(C9,"MMM")) | E9: Hoist | F9: Construction | G9: Office | H9: Priya Sharma | I9: 12 | J9: 3 | K9: 2 | L9: Good | M9: Pending | N9: Clean area | O9: 46204
A10: 5 | B10: EQI-005 | C10: 46335 | D10: =IF(C10="","",TEXT(C10,"MMM")) | E10: Generator | F10: Engineering | G10: Tank Farm | H10: Sarah Wilson | I10: 7 | J10: 0 | K10: 0 | L10: Good | M10: Completed | N10: Replace equipment | O10: 46292
A11: 6 | B11: EQI-006 | C11: 46283 | D11: =IF(C11="","",TEXT(C11,"MMM")) | E11: Generator | F11: Maintenance | G11: Office | H11: Fatima Al-Said | I11: 18 | J11: 5 | K11: 0 | L11: Unsatisfactory | M11: Cancelled | N11: Replace equipment | O11: 46325
A12: 7 | B12: EQI-007 | C12: 46103 | D12: =IF(C12="","",TEXT(C12,"MMM")) | E12: Conveyor | F12: Construction | G12: Plant B | H12: Fatima Al-Said | I12: 16 | J12: 0 | K12: 2 | L12: Excellent | M12: In Progress | N12: Clean area | O12: 46343
A13: 8 | B13: EQI-008 | C13: 46344 | D13: =IF(C13="","",TEXT(C13,"MMM")) | E13: Crane | F13: Contractor | G13: Field Site | H13: Ahmed Khan | I13: 10 | J13: 2 | K13: 2 | L13: Unsatisfactory | M13: Overdue
A14: 9 | B14: EQI-009 | C14: 46100 | D14: =IF(C14="","",TEXT(C14,"MMM")) | E14: Pump | F14: Maintenance | G14: Warehouse | H14: Ahmed Khan | I14: 7 | J14: 5 | K14: 1 | L14: Good | M14: Pending | N14: Clean area | O14: 46213
A15: 10 | B15: EQI-010 | C15: 46198 | D15: =IF(C15="","",TEXT(C15,"MMM")) | E15: Welding Machine | F15: Contractor | G15: Plant B | H15: Ahmed Khan | I15: 9 | J15: 1 | K15: 0 | L15: Satisfactory | M15: Overdue | N15: Clean area | O15: 46275
A16: 11 | B16: EQI-011 | C16: 46212 | D16: =IF(C16="","",TEXT(C16,"MMM")) | E16: Pressure Vessel | F16: Projects | G16: Plant B | H16: Fatima Al-Said | I16: 18 | J16: 0 | K16: 2 | L16: Excellent | M16: Pending | N16: Install guard | O16: 46049
A17: 12 | B17: EQI-012 | C17: 46297 | D17: =IF(C17="","",TEXT(C17,"MMM")) | E17: Crane | F17: Construction | G17: Field Site | H17: Maria Garcia | I17: 9 | J17: 2 | K17: 2 | L17: Unsatisfactory | M17: Completed | O17: 46220
A18: 13 | B18: EQI-013 | C18: 46221 | D18: =IF(C18="","",TEXT(C18,"MMM")) | E18: Pressure Vessel | F18: Projects | G18: Control Room | H18: Sarah Wilson | I18: 17 | J18: 5 | K18: 0 | L18: Good | M18: Completed | N18: Clean area | O18: 46212
A19: 14 | B19: EQI-014 | C19: 46308 | D19: =IF(C19="","",TEXT(C19,"MMM")) | E19: Pump | F19: Safety | G19: Plant B | H19: David Chen | I19: 5 | J19: 2 | K19: 1 | L19: Excellent | M19: Pending | N19: Replace equipment
A20: 15 | B20: EQI-015 | C20: 46061 | D20: =IF(C20="","",TEXT(C20,"MMM")) | E20: Pump | F20: Contractor | G20: Office | H20: Tom Brown | I20: 7 | J20: 3 | K20: 2 | L20: Unsatisfactory | M20: In Progress | N20: Replace equipment | O20: 46097
A21: 16 | B21: EQI-016 | C21: 46070 | D21: =IF(C21="","",TEXT(C21,"MMM")) | E21: Hoist | F21: Construction | G21: Control Room | H21: Fatima Al-Said | I21: 9 | J21: 1 | K21: 0 | L21: Needs Improvement | M21: Overdue | N21: Fix issue
A22: 17 | B22: EQI-017 | C22: 46106 | D22: =IF(C22="","",TEXT(C22,"MMM")) | E22: Forklift | F22: Engineering | G22: Tank Farm | H22: Priya Sharma | I22: 19 | J22: 5 | K22: 2 | L22: Unsatisfactory | M22: In Progress | N22: Clean area
A23: 18 | B23: EQI-018 | C23: 46255 | D23: =IF(C23="","",TEXT(C23,"MMM")) | E23: Compressor | F23: Safety | G23: Plant A | H23: Fatima Al-Said | I23: 7 | J23: 2 | K23: 3 | L23: Good | M23: Completed | O23: 46172
A24: =IF($B24="","",ROW()-5) | D24: =IF($B24="","",IF(C24="","",TEXT(C24,"MMM")))
A25: =IF($B25="","",ROW()-5) | D25: =IF($B25="","",IF(C25="","",TEXT(C25,"MMM")))
A26: =IF($B26="","",ROW()-5) | D26: =IF($B26="","",IF(C26="","",TEXT(C26,"MMM")))
A27: =IF($B27="","",ROW()-5) | D27: =IF($B27="","",IF(C27="","",TEXT(C27,"MMM")))
A28: =IF($B28="","",ROW()-5) | D28: =IF($B28="","",IF(C28="","",TEXT(C28,"MMM")))
A29: =IF($B29="","",ROW()-5) | D29: =IF($B29="","",IF(C29="","",TEXT(C29,"MMM")))
A30: =IF($B30="","",ROW()-5) | D30: =IF($B30="","",IF(C30="","",TEXT(C30,"MMM")))
A31: =IF($B31="","",ROW()-5) | D31: =IF($B31="","",IF(C31="","",TEXT(C31,"MMM")))
A32: =IF($B32="","",ROW()-5) | D32: =IF($B32="","",IF(C32="","",TEXT(C32,"MMM")))
A33: =IF($B33="","",ROW()-5) | D33: =IF($B33="","",IF(C33="","",TEXT(C33,"MMM")))
A34: =IF($B34="","",ROW()-5) | D34: =IF($B34="","",IF(C34="","",TEXT(C34,"MMM")))
A35: =IF($B35="","",ROW()-5) | D35: =IF($B35="","",IF(C35="","",TEXT(C35,"MMM")))
... A506: =IF($B506="","",ROW()-5) | D506: =IF($B506="","",IF(C506="","",TEXT(C506,"MMM")))

Sheet Safety Walkthroughs
A1: 🚶 SAFETY WALKTHROUGHS — DATA ENTRY
A2: 🔵 Blue = User Input | ⚫ Gray = Auto-Calculated | Use dropdowns where available
A3: IDENTIFICATION | E3: SCOPE | F3: ORGANIZATIONAL | H3: PEOPLE | I3: FINDINGS | L3: QUALITY | M3: STATUS | N3: FOLLOW-UP
A4: S.No | B4: Ref No. | C4: Date | D4: Month | E4: Inspection Area/Item | F4: Department | G4: Location | H4: Inspector | I4: Checkpoints Inspected | J4: Non-Conformances | K4: Critical Findings | L4: Overall Rating | M4: Status | N4: Corrective Action | O4: Due Date
A5: ⚙️ AUTO | B5: ✏️ INPUT | C5: ✏️ INPUT | D5: ⚙️ AUTO | E5: ✏️ INPUT | F5: ✏️ INPUT | G5: ✏️ INPUT | H5: ✏️ INPUT | I5: ✏️ INPUT | J5: ✏️ INPUT | K5: ✏️ INPUT | L5: ✏️ INPUT | M5: ✏️ INPUT | N5: ✏️ INPUT | O5: ✏️ INPUT
