Workbook
Name AmberBand: Settings!$C$40
Name BenchLTIFR: Settings!$C$57
Name BenchTRIR: Settings!$C$56
Name CAClosure: Calculations!$DL$57
Name CertValidityDays: Settings!$C$60
Name CostPerDowntimeMin: Settings!$C$43
Name CostPerLostDay: Settings!$C$44
Name CurMonthNo: Calculations!$I$10
Name dCrit: Calculations!$C$7
Name dCrit: IF(SelDept="All","<>",SelDept)
Name F_Dept: 'Master Data'!$J$5:$J$15
Name F_Month: 'Master Data'!$I$5:$I$17
Name F_Period: 'Master Data'!$K$5:$K$20
Name gdAlcoholPositive: Calculations!$DO$23
Name gdAlcoholTests: Calculations!$DO$53
Name gdBulletinReach: Calculations!$DO$40
Name gdCAClosure: Calculations!$DO$57
Name gdCorrectiveActions: Calculations!$DO$56
Name gdDisciplinary: Calculations!$DO$20
Name gdDrillParticipation: Calculations!$DO$42
Name gdEmergencyDrills: Calculations!$DO$41
Name gdEquipmentCriticalFindings: Calculations!$DO$35
Name gdEquipmentInspections: Calculations!$DO$34
Name gdExternalAuditNCs: Calculations!$DO$46
Name gdExternalAudits: Calculations!$DO$45
Name gdFirstAid: Calculations!$DO$18
Name gdHSEObservations: Calculations!$DO$30
Name gdInternalAuditNCs: Calculations!$DO$44
Name gdInternalAudits: Calculations!$DO$43
Name gdJSAApproved: Calculations!$DO$27
Name gdJSAAssessments: Calculations!$DO$26
Name gdLostDays: Calculations!$DO$19
Name gdLTIFatality: Calculations!$DO$16
Name gdLTIFR: Calculations!$DO$13
Name gdManagementReviews: Calculations!$DO$49
Name gdManagementVisits: Calculations!$DO$47
Name gdMeetingsCloseout: Calculations!$DO$38
Name gdMgmtReviewAttendance: Calculations!$DO$50
Name gdMgmtVisitCloseout: Calculations!$DO$48
Name gdNCClosure: Calculations!$DO$22
Name gdNearMiss: Calculations!$DO$17
Name gdObsClosure: Calculations!$DO$31
Name gdOpenNCs: Calculations!$DO$21
Name gdPTWAudits: Calculations!$DO$54
Name gdPTWCompliance: Calculations!$DO$55
Name gdRecordable: Calculations!$DO$15
Name gdSafetyAwards: Calculations!$DO$51
Name gdSafetyBulletins: Calculations!$DO$39
Name gdSafetyMeetings: Calculations!$DO$37
Name gdSafetyWalkthroughs: Calculations!$DO$36
Name gdStopWorkAuthority: Calculations!$DO$52
Name gdToolboxAvgAttendance: Calculations!$DO$25
Name gdToolboxTalks: Calculations!$DO$24
Name gdTotalIncidents: Calculations!$DO$14
Name gdTrainingCompliance: Calculations!$DO$29
Name gdTrainings: Calculations!$DO$28
Name gdTRIR: Calculations!$DO$12
Name gdUnsafeActClosure: Calculations!$DO$59
Name gdUnsafeActsReported: Calculations!$DO$58
Name gdUnsafeConditionClosure: Calculations!$DO$61

Sheet Toolbox Talks
A1: 🗣️ TOOLBOX TALKS — DATA ENTRY | Q1: Home
A2: Blue = user input · Gray = auto-calculated · use dropdowns where available
A3: S.No | B3: Ref No. | C3: Date | D3: Month | E3: Topic | F3: Department | G3: Location | H3: Conducted By | I3: Target Attendees | J3: Actual Attendees | K3: Attendance % | L3: Duration (min) | M3: Safety Category | N3: Action Required | O3: Effectiveness
A4: 1 | B4: TBT-1035 | C4: 46040 | D4: Jan | E4: Manual Handling | F4: Logistics | G4: Boiler House | H4: A. Sharma | I4: 56 | J4: 17 | K4: =IFERROR(J4/I4*100,0) -> 0 | L4: 35 | M4: Ergonomics | N4: Yes | O4: Excellent
A5: 2 | B5: TBT-1036 | C5: 46027 | D5: Jan | E5: Chemical Safety | F5: Projects | G5: ETP Plant | H5: D. Singh | I5: 51 | J5: 29 | K5: =IFERROR(J5/I5*100,0) -> 0 | L5: 18 | M5: Housekeeping | N5: Yes | O5: Satisfactory
A6: 3 | B6: TBT-1001 | C6: 46064 | D6: Feb | E6: Slip Trip Fall | F6: Projects | G6: Admin Block | H6: G. Das | I6: 16 | J6: 24 | K6: =IFERROR(J6/I6*100,0) -> 0 | L6: 91 | M6: Ergonomics | N6: No | O6: Unsatisfactory
A7: 4 | B7: TBT-1003 | C7: 46068 | D7: Feb | E7: Machine Guarding | F7: Operations | G7: Admin Block | H7: T. Bose | I7: 53 | J7: 30 | K7: =IFERROR(J7/I7*100,0) -> 0 | L7: 41 | M7: Housekeeping | N7: No | O7: Satisfactory
A8: 5 | B8: TBT-1029 | C8: 46075 | D8: Feb | E8: Hot Work | F8: Operations | G8: Control Room | H8: L. Fernandes | I8: 21 | J8: 51 | K8: =IFERROR(J8/I8*100,0) -> 0 | L8: 95 | M8: BBS | N8: No | O8: Satisfactory
A9: 6 | B9: TBT-1044 | C9: 46063 | D9: Feb | E9: Slip Trip Fall | F9: Logistics | G9: Loading Bay | H9: P. Nair | I9: 18 | J9: 55 | K9: =IFERROR(J9/I9*100,0) -> 0 | L9: 109 | M9: BBS | N9: Yes | O9: Unsatisfactory
A10: 7 | B10: TBT-1046 | C10: 46056 | D10: Feb | E10: Emergency Procedures | F10: Engineering | G10: Office | H10: K. Reddy | I10: 45 | J10: 26 | K10: =IFERROR(J10/I10*100,0) -> 0 | L10: 54 | M10: BBS | N10: Yes | O10: Good
A11: 8 | B11: TBT-1013 | C11: 46095 | D11: Mar | E11: Fire Safety | F11: Admin | G11: Admin Block | H11: P. Nair | I11: 41 | J11: 33 | K11: =IFERROR(J11/I11*100,0) -> 0 | L11: 27 | M11: General | N11: No | O11: Good
A12: 9 | B12: TBT-1043 | C12: 46102 | D12: Mar | E12: Working at Heights | F12: Quality | G12: Tank Farm | H12: A. Sharma | I12: 32 | J12: 43 | K12: =IFERROR(J12/I12*100,0) -> 0 | L12: 104 | M12: Housekeeping | N12: Yes | O12: Good
A13: 10 | B13: TBT-1042 | C13: 46124 | D13: Apr | E13: Heat Stress | F13: Logistics | G13: Admin Block | H13: T. Bose | I13: 45 | J13: 40 | K13: =IFERROR(J13/I13*100,0) -> 0 | L13: 115 | M13: Process Safety | N13: No | O13: Good
A14: 11 | B14: TBT-1045 | C14: 46140 | D14: Apr | E14: Electrical Safety | F14: Contractor | G14: ETP Plant | H14: A. Sharma | I14: 35 | J14: 34 | K14: =IFERROR(J14/I14*100,0) -> 0 | L14: 83 | M14: Ergonomics | N14: Yes | O14: Unsatisfactory
A15: 12 | B15: TBT-1007 | C15: 46170 | D15: May | E15: Confined Space | F15: Quality | G15: Tank Farm | H15: V. Rao | I15: 43 | J15: 11 | K15: =IFERROR(J15/I15*100,0) -> 0 | L15: 88 | M15: General | N15: Yes | O15: Excellent
... A51: 48 | B51: TBT-1017 | C51: 46373 | D51: Dec | E51: Fire Safety | F51: Safety | G51: Office | H51: D. Singh | I51: 20 | J51: 18 | K51: =IFERROR(J51/I51*100,0) -> 0 | L51: 115 | M51: Ergonomics | N51: No | O51: Unsatisfactory
K52: =IFERROR(J52/I52*100,0) -> 0
K53: =IFERROR(J53/I53*100,0) -> 0
K54: =IFERROR(J54/I54*100,0) -> 0
K55: =IFERROR(J55/I55*100,0) -> 0
K56: =IFERROR(J56/I56*100,0) -> 0
K57: =IFERROR(J57/I57*100,0) -> 0
K58: =IFERROR(J58/I58*100,0) -> 0
K59: =IFERROR(J59/I59*100,0) -> 0
K60: =IFERROR(J60/I60*100,0) -> 0
K61: =IFERROR(J61/I61*100,0) -> 0
K62: =IFERROR(J62/I62*100,0) -> 0
K63: =IFERROR(J63/I63*100,0) -> 0
... K1003: =IFERROR(J1003/I1003*100,0) -> 0

Sheet JSA Risk Assessment
A1: ⚠️ JSA RISK ASSESSMENT — DATA ENTRY | S1: Home
A2: Blue = user input · Gray = auto-calculated · use dropdowns where available
A3: S.No | B3: JSA No. | C3: Date | D3: Month | E3: Task/Activity | F3: Department | G3: Location | H3: Assessed By | I3: Approved By | J3: Risk Level | K3: Hazards Identified | L3: Assessment Type | M3: Approval Status | N3: Controls Implemented | O3: Compliance | P3: Likelihood | Q3: Consequence
A4: 1 | B4: JSA-1019 | C4: 46031 | D4: Jan | E4: Machine Guarding | F4: Safety | G4: Warehouse | H4: S. Iyer | I4: P. Nair | J4: Low | K4: 5 | L4: Task RA | M4: Approved | N4: Working at Heights | O4: Partially Compliant | P4: 1 | Q4: 1
A5: 2 | B5: JSA-1007 | C5: 46062 | D5: Feb | E5: Confined Space | F5: Safety | G5: Tank Farm | H5: D. Singh | I5: J. Mehta | J5: Medium | K5: 8 | L5: JSA | M5: Approved | N5: Housekeeping | O5: Non-Compliant | P5: 1 | Q5: 3
A6: 3 | B6: JSA-1031 | C6: 46072 | D6: Feb | E6: Confined Space | F6: Admin | G6: Office | H6: T. Bose | I6: V. Rao | J6: Critical | K6: 3 | L6: What-If | M6: Pending Review | N6: Slip Trip Fall | O6: Non-Compliant | P6: 3 | Q6: 1
A7: 4 | B7: JSA-1036 | C7: 46062 | D7: Feb | E7: PPE Usage | F7: Construction | G7: Field Site | H7: N. Gupta | I7: D. Singh | J7: Critical | K7: 4 | L7: HIRA | M7: Revision Required | N7: Emergency Procedures | O7: Partially Compliant | P7: 1 | Q7: 3
A8: 5 | B8: JSA-1001 | C8: 46087 | D8: Mar | E8: Fire Safety | F8: Operations | G8: Boiler House | H8: D. Singh | I8: L. Fernandes | J8: Medium | K8: 0 | L8: HAZOP | M8: Approved | N8: Electrical Safety | O8: Compliant | P8: 2 | Q8: 3
A9: 6 | B9: JSA-1016 | C9: 46106 | D9: Mar | E9: Machine Guarding | F9: Safety | G9: Boiler House | H9: V. Rao | I9: G. Das | J9: Medium | K9: 1 | L9: Bow Tie | M9: Rejected | N9: PPE Usage | O9: Non-Compliant | P9: 1 | Q9: 2
A10: 7 | B10: JSA-1020 | C10: 46095 | D10: Mar | E10: Heat Stress | F10: Contractor | G10: Boiler House | H10: A. Sharma | I10: P. Nair | J10: High | K10: 5 | L10: Bow Tie | M10: Approved | N10: LOTO | O10: Partially Compliant | P10: 2 | Q10: 4
A11: 8 | B11: JSA-1021 | C11: 46104 | D11: Mar | E11: PPE Usage | F11: Projects | G11: Tank Farm | H11: A. Sharma | I11: A. Sharma | J11: High | K11: 4 | L11: HAZOP | M11: Pending Review | N11: Working at Heights | O11: Partially Compliant | P11: 1 | Q11: 4
A12: 9 | B12: JSA-1026 | C12: 46099 | D12: Mar | E12: Chemical Safety | F12: Construction | G12: Tank Farm | H12: J. Mehta | I12: N. Gupta | J12: Medium | K12: 0 | L12: JSA | M12: Pending Review | N12: Chemical Safety | O12: Non-Compliant | P12: 5 | Q12: 1
A13: 10 | B13: JSA-1029 | C13: 46099 | D13: Mar | E13: PPE Usage | F13: Safety | G13: Plant A | H13: L. Fernandes | I13: R. Verma | J13: Low | K13: 8 | L13: HIRA | M13: Pending Review | N13: Machine Guarding | O13: Non-Compliant | P13: 3 | Q13: 2
A14: 11 | B14: JSA-1034 | C14: 46098 | D14: Mar | E14: Chemical Safety | F14: Safety | G14: Plant B | H14: P. Nair | I14: S. Iyer | J14: Low | K14: 0 | L14: Task RA | M14: Pending Review | N14: LOTO | O14: Partially Compliant | P14: 2 | Q14: 4
A15: 12 | B15: JSA-1040 | C15: 46082 | D15: Mar | E15: Fire Safety | F15: Quality | G15: Loading Bay | H15: T. Bose | I15: D. Singh | J15: Medium | K15: 5 | L15: Bow Tie | M15: Rejected | N15: Fire Safety | O15: Partially Compliant | P15: 3 | Q15: 1
... A51: 48 | B51: JSA-1042 | C51: 46371 | D51: Dec | E51: Fire Safety | F51: Contractor | G51: Workshop | H51: D. Singh | I51: T. Bose | J51: Low | K51: 2 | L51: Bow Tie | M51: Rejected | N51: LOTO | O51: Non-Compliant | P51: 1 | Q51: 1

Sheet Training
A1: 🎓 TRAINING — DATA ENTRY | S1: Home
A2: Blue = user input · Gray = auto-calculated · use dropdowns where available
A3: S.No | B3: Training ID | C3: Date | D3: Month | E3: Course Name | F3: Training Type | G3: Department | H3: Trainer | I3: Mode | J3: Target Attendees | K3: Actual Attendees | L3: Attendance % | M3: Duration (hrs) | N3: Status | O3: Assessment Result | P3: Certificate Issued | Q3: Certificate Expiry
A4: 1 | B4: TRN-1011 | C4: 46040 | D4: Jan | E4: Electrical Safety | F4: Awareness | G4: Contractor | H4: T. Bose | I4: Online | J4: 36 | K4: 57 | L4: =IFERROR(K4/J4*100,0) -> 0 | M4: 48 | N4: Completed | O4: N/A | P4: No | Q4: =IF(P4="Yes",C4+CertValidityDays,"") -> 0
A5: 2 | B5: TRN-1032 | C5: 46043 | D5: Jan | E5: PPE Usage | F5: On-the-Job | G5: Contractor | H5: S. Iyer | I5: On-the-Job | J5: 35 | K5: 17 | L5: =IFERROR(K5/J5*100,0) -> 0 | M5: 106 | N5: In Progress | O5: Fail | P5: Yes | Q5: =IF(P5="Yes",C5+CertValidityDays,"") -> 0
A6: 3 | B6: TRN-1043 | C6: 46041 | D6: Jan | E6: Heat Stress | F6: Induction | G6: Maintenance | H6: M. Khan | I6: External | J6: 41 | K6: 22 | L6: =IFERROR(K6/J6*100,0) -> 0 | M6: 43 | N6: Completed | O6: Fail | P6: Yes | Q6: =IF(P6="Yes",C6+CertValidityDays,"") -> 0
A7: 4 | B7: TRN-1044 | C7: 46032 | D7: Jan | E7: Slip Trip Fall | F7: On-the-Job | G7: Projects | H7: T. Bose | I7: Internal | J7: 36 | K7: 55 | L7: =IFERROR(K7/J7*100,0) -> 0 | M7: 66 | N7: In Progress | O7: Pass | P7: No | Q7: =IF(P7="Yes",C7+CertValidityDays,"") -> 0
A8: 5 | B8: TRN-1010 | C8: 46072 | D8: Feb | E8: Electrical Safety | F8: Advanced | G8: Contractor | H8: J. Mehta | I8: Online | J8: 24 | K8: 57 | L8: =IFERROR(K8/J8*100,0) -> 0 | M8: 120 | N8: Scheduled | O8: Pass | P8: No | Q8: =IF(P8="Yes",C8+CertValidityDays,"") -> 0
A9: 6 | B9: TRN-1018 | C9: 46057 | D9: Feb | E9: Confined Space | F9: Competency | G9: Maintenance | H9: L. Fernandes | I9: On-the-Job | J9: 12 | K9: 18 | L9: =IFERROR(K9/J9*100,0) -> 0 | M9: 71 | N9: In Progress | O9: N/A | P9: Yes | Q9: =IF(P9="Yes",C9+CertValidityDays,"") -> 0
A10: 7 | B10: TRN-1021 | C10: 46079 | D10: Feb | E10: Housekeeping | F10: Refresher | G10: Engineering | H10: P. Nair | I10: On-the-Job | J10: 43 | K10: 49 | L10: =IFERROR(K10/J10*100,0) -> 0 | M10: 34 | N10: Completed | O10: Pass | P10: No | Q10: =IF(P10="Yes",C10+CertValidityDays,"") -> 0
A11: 8 | B11: TRN-1022 | C11: 46060 | D11: Feb | E11: Housekeeping | F11: Induction | G11: Admin | H11: K. Reddy | I11: On-the-Job | J11: 14 | K11: 10 | L11: =IFERROR(K11/J11*100,0) -> 0 | M11: 61 | N11: Scheduled | O11: Pass | P11: No | Q11: =IF(P11="Yes",C11+CertValidityDays,"") -> 0
A12: 9 | B12: TRN-1033 | C12: 46061 | D12: Feb | E12: Manual Handling | F12: Competency | G12: Quality | H12: M. Khan | I12: Online | J12: 23 | K12: 39 | L12: =IFERROR(K12/J12*100,0) -> 0 | M12: 102 | N12: Completed | O12: Pass | P12: No | Q12: =IF(P12="Yes",C12+CertValidityDays,"") -> 0
A13: 10 | B13: TRN-1038 | C13: 46074 | D13: Feb | E13: Electrical Safety | F13: On-the-Job | G13: Operations | H13: K. Reddy | I13: Internal | J13: 58 | K13: 34 | L13: =IFERROR(K13/J13*100,0) -> 0 | M13: 82 | N13: Completed | O13: N/A | P13: No | Q13: =IF(P13="Yes",C13+CertValidityDays,"") -> 0
A14: 11 | B14: TRN-1039 | C14: 46057 | D14: Feb | E14: Fire Safety | F14: Competency | G14: Safety | H14: A. Sharma | I14: External | J14: 25 | K14: 30 | L14: =IFERROR(K14/J14*100,0) -> 0 | M14: 118 | N14: Scheduled | O14: Fail | P14: Yes | Q14: =IF(P14="Yes",C14+CertValidityDays,"") -> 0
A15: 12 | B15: TRN-1007 | C15: 46084 | D15: Mar | E15: LOTO | F15: On-the-Job | G15: Operations | H15: J. Mehta | I15: Internal | J15: 38 | K15: 41 | L15: =IFERROR(K15/J15*100,0) -> 0 | M15: 22 | N15: Completed | O15: Fail | P15: Yes | Q15: =IF(P15="Yes",C15+CertValidityDays,"") -> 0
... A51: 48 | B51: TRN-1017 | C51: 46368 | D51: Dec | E51: Slip Trip Fall | F51: On-the-Job | G51: Contractor | H51: R. Verma | I51: Internal | J51: 28 | K51: 18 | L51: =IFERROR(K51/J51*100,0) -> 0 | M51: 28 | N51: In Progress | O51: Pass | P51: Yes | Q51: =IF(P51="Yes",C51+CertValidityDays,"") -> 0
L52: =IFERROR(K52/J52*100,0) -> 0 | Q52: =IF(P52="Yes",C52+CertValidityDays,"") -> 0
L53: =IFERROR(K53/J53*100,0) -> 0 | Q53: =IF(P53="Yes",C53+CertValidityDays,"") -> 0
L54: =IFERROR(K54/J54*100,0) -> 0 | Q54: =IF(P54="Yes",C54+CertValidityDays,"") -> 0
L55: =IFERROR(K55/J55*100,0) -> 0 | Q55: =IF(P55="Yes",C55+CertValidityDays,"") -> 0
L56: =IFERROR(K56/J56*100,0) -> 0 | Q56: =IF(P56="Yes",C56+CertValidityDays,"") -> 0
L57: =IFERROR(K57/J57*100,0) -> 0 | Q57: =IF(P57="Yes",C57+CertValidityDays,"") -> 0
L58: =IFERROR(K58/J58*100,0) -> 0 | Q58: =IF(P58="Yes",C58+CertValidityDays,"") -> 0
L59: =IFERROR(K59/J59*100,0) -> 0 | Q59: =IF(P59="Yes",C59+CertValidityDays,"") -> 0
L60: =IFERROR(K60/J60*100,0) -> 0 | Q60: =IF(P60="Yes",C60+CertValidityDays,"") -> 0
L61: =IFERROR(K61/J61*100,0) -> 0 | Q61: =IF(P61="Yes",C61+CertValidityDays,"") -> 0
L62: =IFERROR(K62/J62*100,0) -> 0 | Q62: =IF(P62="Yes",C62+CertValidityDays,"") -> 0
L63: =IFERROR(K63/J63*100,0) -> 0 | Q63: =IF(P63="Yes",C63+CertValidityDays,"") -> 0
... L1003: =IFERROR(K1003/J1003*100,0) -> 0 | Q1003: =IF(P1003="Yes",C1003+CertValidityDays,"") -> 0

Sheet HSE Observations
A1: 👁️ HSE OBSERVATIONS — DATA ENTRY | Q1: Home
A2: Blue = user input · Gray = auto-calculated · use dropdowns where available
A3: S.No | B3: Obs No. | C3: Date | D3: Month | E3: Observation Type | F3: Description | G3: Department | H3: Location | I3: Observed By | J3: Responsible Person | K3: Category | L3: Risk Level | M3: Status | N3: Action Taken | O3: Due Date
A4: 1 | B4: OBS-1027 | C4: 46030 | D4: Jan | E4: Safe Act | F4: Chemical Safety | G4: Admin | H4: Office | I4: V. Rao | J4: M. Khan | K4: General | L4: Low | M4: Completed | N4: Verbal Warning | O4: 46065
A5: 2 | B5: OBS-1031 | C5: 46028 | D5: Jan | E5: Unsafe Condition | F5: Working at Heights | G5: Projects | H5: Plant A | I5: G. Das | J5: T. Bose | K5: BBS | L5: Low | M5: In Progress | N5: Retraining | O5: 46072
A6: 3 | B6: OBS-1036 | C6: 46048 | D6: Jan | E6: Safe Act | F6: Fire Safety | G6: Construction | H6: Warehouse | I6: L. Fernandes | J6: J. Mehta | K6: Process Safety | L6: Medium | M6: Completed | N6: Fine | O6: 46063
A7: 4 | B7: OBS-1046 | C7: 46044 | D7: Jan | E7: Unsafe Act | F7: Confined Space | G7: Engineering | H7: Loading Bay | I7: A. Sharma | J7: G. Das | K7: Process Safety | L7: Medium | M7: Pending | N7: Verbal Warning | O7: 46084
A8: 5 | B8: OBS-1004 | C8: 46066 | D8: Feb | E8: Unsafe Act | F8: Machine Guarding | G8: Admin | H8: Boiler House | I8: S. Iyer | J8: G. Das | K8: PPE | L8: Medium | M8: Completed | N8: Fine | O8: 46076
A9: 6 | B9: OBS-1009 | C9: 46064 | D9: Feb | E9: Unsafe Act | F9: Slip Trip Fall | G9: Maintenance | H9: Plant A | I9: G. Das | J9: R. Verma | K9: General | L9: High | M9: In Progress | N9: Suspension | O9: 46080
A10: 7 | B10: OBS-1017 | C10: 46066 | D10: Feb | E10: Safe Act | F10: LOTO | G10: Maintenance | H10: Plant A | I10: S. Iyer | J10: S. Iyer | K10: PPE | L10: Critical | M10: Completed | N10: Written Warning | O10: 46071
A11: 8 | B11: OBS-1019 | C11: 46072 | D11: Feb | E11: Near Miss | F11: Working at Heights | G11: Operations | H11: Workshop | I11: V. Rao | J11: J. Mehta | K11: Process Safety | L11: Medium | M11: Pending | N11: Suspension | O11: 46085
A12: 9 | B12: OBS-1042 | C12: 46063 | D12: Feb | E12: Safe Act | F12: PPE Usage | G12: Projects | H12: Plant B | I12: M. Khan | J12: H. Patel | K12: General | L12: High | M12: Pending | N12: Retraining | O12: 46070
A13: 10 | B13: OBS-1044 | C13: 46054 | D13: Feb | E13: Safe Act | F13: Confined Space | G13: Maintenance | H13: Loading Bay | I13: G. Das | J13: K. Reddy | K13: Process Safety | L13: Low | M13: Completed | N13: Suspension | O13: 46078
A14: 11 | B14: OBS-1005 | C14: 46090 | D14: Mar | E14: Unsafe Act | F14: LOTO | G14: Maintenance | H14: Admin Block | I14: L. Fernandes | J14: S. Iyer | K14: Housekeeping | L14: Medium | M14: Pending | N14: Retraining | O14: 46120
A15: 12 | B15: OBS-1006 | C15: 46098 | D15: Mar | E15: Safe Condition | F15: LOTO | G15: Engineering | H15: ETP Plant | I15: H. Patel | J15: S. Iyer | K15: BBS | L15: Medium | M15: Pending | N15: Written Warning | O15: 46122
... A51: 48 | B51: OBS-1040 | C51: 46365 | D51: Dec | E51: Safe Act | F51: Machine Guarding | G51: Logistics | H51: Plant B | I51: R. Verma | J51: P. Nair | K51: PPE | L51: Medium | M51: Pending | N51: Retraining | O51: 46372

Sheet Workplace Inspections
A1: 🔍 WORKPLACE INSPECTIONS — DATA ENTRY | Q1: Home
A2: Blue = user input · Gray = auto-calculated · use dropdowns where available
A3: S.No | B3: Ref No. | C3: Date | D3: Month | E3: Inspection Area/Item | F3: Department | G3: Location | H3: Inspector | I3: Checkpoints Inspected | J3: Non-Conformances | K3: Critical Findings | L3: Overall Rating | M3: Status | N3: Corrective Action | O3: Due Date
A4: 1 | B4: WPI-1010 | C4: 46028 | D4: Jan | E4: Field Site | F4: Projects | G4: Boiler House | H4: K. Reddy | I4: 23 | J4: 5 | K4: 8 | L4: Excellent | M4: Pending | N4: LOTO | O4: 46056
A5: 2 | B5: WPI-1007 | C5: 46070 | D5: Feb | E5: Plant B | F5: Quality | G5: Workshop | H5: D. Singh | I5: 31 | J5: 0 | K5: 6 | L5: Unsatisfactory | M5: In Progress | N5: Housekeeping | O5: 46089
A6: 3 | B6: WPI-1008 | C6: 46062 | D6: Feb | E6: ETP Plant | F6: Construction | G6: Admin Block | H6: G. Das | I6: 38 | J6: 4 | K6: 6 | L6: Excellent | M6: In Progress | N6: Emergency Procedures | O6: 46095
A7: 4 | B7: WPI-1023 | C7: 46063 | D7: Feb | E7: Workshop | F7: Construction | G7: Control Room | H7: N. Gupta | I7: 20 | J7: 8 | K7: 3 | L7: Unsatisfactory | M7: Completed | N7: Electrical Safety | O7: 46107
A8: 5 | B8: WPI-1025 | C8: 46058 | D8: Feb | E8: Loading Bay | F8: Logistics | G8: Warehouse | H8: A. Sharma | I8: 34 | J8: 2 | K8: 6 | L8: Satisfactory | M8: Pending | N8: Fire Safety | O8: 46087
A9: 6 | B9: WPI-1033 | C9: 46073 | D9: Feb | E9: Control Room | F9: Contractor | G9: Loading Bay | H9: G. Das | I9: 38 | J9: 3 | K9: 2 | L9: Unsatisfactory | M9: Pending | N9: Slip Trip Fall | O9: 46083
A10: 7 | B10: WPI-1044 | C10: 46066 | D10: Feb | E10: Office | F10: Contractor | G10: Tank Farm | H10: J. Mehta | I10: 34 | J10: 4 | K10: 7 | L10: Unsatisfactory | M10: In Progress | N10: Slip Trip Fall | O10: 46086
A11: 8 | B11: WPI-1016 | C11: 46101 | D11: Mar | E11: Workshop | F11: Operations | G11: Control Room | H11: T. Bose | I11: 36 | J11: 0 | K11: 5 | L11: Unsatisfactory | M11: Completed | N11: Machine Guarding | O11: 46137
A12: 9 | B12: WPI-1026 | C12: 46094 | D12: Mar | E12: Control Room | F12: Contractor | G12: Boiler House | H12: M. Khan | I12: 37 | J12: 0 | K12: 2 | L12: Needs Improvement | M12: Pending | N12: PPE Usage | O12: 46122
A13: 10 | B13: WPI-1027 | C13: 46099 | D13: Mar | E13: Control Room | F13: Quality | G13: Loading Bay | H13: N. Gupta | I13: 34 | J13: 6 | K13: 0 | L13: Satisfactory | M13: Completed | N13: Machine Guarding | O13: 46144
A14: 11 | B14: WPI-1030 | C14: 46094 | D14: Mar | E14: Field Site | F14: Logistics | G14: ETP Plant | H14: H. Patel | I14: 17 | J14: 8 | K14: 8 | L14: Good | M14: Completed | N14: Slip Trip Fall | O14: 46116
A15: 12 | B15: WPI-1039 | C15: 46097 | D15: Mar | E15: Workshop | F15: Safety | G15: Office | H15: D. Singh | I15: 50 | J15: 0 | K15: 4 | L15: Good | M15: Completed | N15: Electrical Safety | O15: 46108
... A51: 48 | B51: WPI-1037 | C51: 46362 | D51: Dec | E51: Tank Farm | F51: Logistics | G51: Control Room | H51: L. Fernandes | I51: 30 | J51: 7 | K51: 0 | L51: Needs Improvement | M51: Completed | N51: Slip Trip Fall | O51: 46367

Sheet Equipment Inspections
A1: 🛠️ EQUIPMENT INSPECTIONS — DATA ENTRY | Q1: Home
A2: Blue = user input · Gray = auto-calculated · use dropdowns where available
A3: S.No | B3: Ref No. | C3: Date | D3: Month | E3: Inspection Area/Item | F3: Department | G3: Location | H3: Inspector | I3: Checkpoints Inspected | J3: Non-Conformances | K3: Critical Findings | L3: Overall Rating | M3: Status | N3: Corrective Action | O3: Due Date
A4: 1 | B4: EQI-1009 | C4: 46024 | D4: Jan | E4: Tank Farm | F4: Safety | G4: Plant B | H4: H. Patel | I4: 50 | J4: 4 | K4: 8 | L4: Excellent | M4: In Progress | N4: Slip Trip Fall | O4: 46039
A5: 2 | B5: EQI-1013 | C5: 46031 | D5: Jan | E5: Admin Block | F5: Contractor | G5: ETP Plant | H5: T. Bose | I5: 21 | J5: 6 | K5: 2 | L5: Good | M5: Pending | N5: Emergency Procedures | O5: 46047
A6: 3 | B6: EQI-1016 | C6: 46043 | D6: Jan | E6: Workshop | F6: Safety | G6: Control Room | H6: R. Verma | I6: 43 | J6: 6 | K6: 0 | L6: Satisfactory | M6: Completed | N6: Manual Handling | O6: 46083
A7: 4 | B7: EQI-1021 | C7: 46042 | D7: Jan | E7: Plant A | F7: Construction | G7: Office | H7: K. Reddy | I7: 32 | J7: 7 | K7: 7 | L7: Excellent | M7: Completed | N7: Manual Handling | O7: 46078
A8: 5 | B8: EQI-1024 | C8: 46025 | D8: Jan | E8: Plant B | F8: Engineering | G8: Warehouse | H8: D. Singh | I8: 18 | J8: 6 | K8: 6 | L8: Needs Improvement | M8: Completed | N8: Machine Guarding | O8: 46030
A9: 6 | B9: EQI-1040 | C9: 46024 | D9: Jan | E9: Admin Block | F9: Construction | G9: Field Site | H9: J. Mehta | I9: 48 | J9: 4 | K9: 2 | L9: Excellent | M9: Pending | N9: Electrical Safety | O9: 46031
A10: 7 | B10: EQI-1044 | C10: 46026 | D10: Jan | E10: Warehouse | F10: Admin | G10: Tank Farm | H10: R. Verma | I10: 44 | J10: 2 | K10: 2 | L10: Satisfactory | M10: Overdue | N10: Machine Guarding | O10: 46068
A11: 8 | B11: EQI-1046 | C11: 46045 | D11: Jan | E11: Office | F11: Engineering | G11: Field Site | H11: L. Fernandes | I11: 32 | J11: 0 | K11: 8 | L11: Excellent | M11: In Progress | N11: Confined Space | O11: 46071
A12: 9 | B12: EQI-1017 | C12: 46079 | D12: Feb | E12: Warehouse | F12: Admin | G12: Plant B | H12: J. Mehta | I12: 49 | J12: 3 | K12: 5 | L12: Needs Improvement | M12: In Progress | N12: Fire Safety | O12: 46111
A13: 10 | B13: EQI-1023 | C13: 46066 | D13: Feb | E13: Boiler House | F13: Maintenance | G13: Boiler House | H13: R. Verma | I13: 31 | J13: 4 | K13: 3 | L13: Good | M13: Completed | N13: Hot Work | O13: 46072
A14: 11 | B14: EQI-1033 | C14: 46074 | D14: Feb | E14: Plant B | F14: Maintenance | G14: Plant B | H14: J. Mehta | I14: 47 | J14: 7 | K14: 2 | L14: Unsatisfactory | M14: In Progress | N14: Electrical Safety | O14: 46081
A15: 12 | B15: EQI-1034 | C15: 46076 | D15: Feb | E15: Office | F15: Logistics | G15: Tank Farm | H15: S. Iyer | I15: 21 | J15: 6 | K15: 1 | L15: Excellent | M15: Pending | N15: LOTO | O15: 46087
... A51: 48 | B51: EQI-1035 | C51: 46360 | D51: Dec | E51: Boiler House | F51: Quality | G51: Field Site | H51: P. Nair | I51: 37 | J51: 5 | K51: 8 | L51: Satisfactory | M51: In Progress | N51: Confined Space | O51: 46386

Sheet Safety Walkthroughs
A1: 🚶 SAFETY WALKTHROUGHS — DATA ENTRY | Q1: Home
A2: Blue = user input · Gray = auto-calculated · use dropdowns where available
A3: S.No | B3: Ref No. | C3: Date | D3: Month | E3: Inspection Area/Item | F3: Department | G3: Location | H3: Inspector | I3: Checkpoints Inspected | J3: Non-Conformances | K3: Critical Findings | L3: Overall Rating | M3: Status | N3: Corrective Action | O3: Due Date
A4: 1 | B4: SW-1020 | C4: 46037 | D4: Jan | E4: Workshop | F4: Maintenance | G4: Control Room | H4: M. Khan | I4: 34 | J4: 3 | K4: 6 | L4: Unsatisfactory | M4: Completed | N4: Housekeeping | O4: 46071
A5: 2 | B5: SW-1033 | C5: 46023 | D5: Jan | E5: Field Site | F5: Logistics | G5: Office | H5: K. Reddy | I5: 50 | J5: 6 | K5: 5 | L5: Unsatisfactory | M5: Completed | N5: LOTO | O5: 46053
A6: 3 | B6: SW-1036 | C6: 46031 | D6: Jan | E6: Loading Bay | F6: Operations | G6: Admin Block | H6: G. Das | I6: 22 | J6: 4 | K6: 8 | L6: Needs Improvement | M6: Overdue | N6: LOTO | O6: 46047
A7: 4 | B7: SW-1041 | C7: 46040 | D7: Jan | E7: ETP Plant | F7: Maintenance | G7: Loading Bay | H7: K. Reddy | I7: 15 | J7: 7 | K7: 3 | L7: Unsatisfactory | M7: Overdue | N7: Confined Space | O7: 46054
A8: 5 | B8: SW-1044 | C8: 46042 | D8: Jan | E8: Field Site | F8: Construction | G8: Admin Block | H8: S. Iyer | I8: 28 | J8: 0 | K8: 4 | L8: Excellent | M8: Pending | N8: Electrical Safety | O8: 46051
A9: 6 | B9: SW-1015 | C9: 46055 | D9: Feb | E9: Control Room | F9: Contractor | G9: Plant B | H9: D. Singh | I9: 19 | J9: 7 | K9: 0 | L9: Good | M9: Completed | N9: Machine Guarding | O9: 46082
A10: 7 | B10: SW-1023 | C10: 46073 | D10: Feb | E10: Plant B | F10: Admin | G10: Plant B | H10: A. Sharma | I10: 15 | J10: 5 | K10: 2 | L10: Satisfactory | M10: In Progress | N10: PPE Usage | O10: 46107
A11: 8 | B11: SW-1034 | C11: 46072 | D11: Feb | E11: Tank Farm | F11: Logistics | G11: Workshop | H11: H. Patel | I11: 31 | J11: 8 | K11: 1 | L11: Good | M11: Completed | N11: Slip Trip Fall | O11: 46097
A12: 9 | B12: SW-1043 | C12: 46072 | D12: Feb | E12: Admin Block | F12: Quality | G12: Office | H12: V. Rao | I12: 27 | J12: 1 | K12: 4 | L12: Unsatisfactory | M12: In Progress | N12: Slip Trip Fall | O12: 46099
A13: 10 | B13: SW-1016 | C13: 46084 | D13: Mar | E13: Warehouse | F13: Quality | G13: Plant B | H13: P. Nair | I13: 31 | J13: 6 | K13: 1 | L13: Good | M13: Completed | N13: Manual Handling | O13: 46128
A14: 11 | B14: SW-1029 | C14: 46103 | D14: Mar | E14: Field Site | F14: Operations | G14: Office | H14: V. Rao | I14: 46 | J14: 0 | K14: 1 | L14: Excellent | M14: Completed | N14: Fire Safety | O14: 46129
A15: 12 | B15: SW-1039 | C15: 46097 | D15: Mar | E15: Field Site | F15: Engineering | G15: Workshop | H15: G. Das | I15: 25 | J15: 8 | K15: 6 | L15: Unsatisfactory | M15: Completed | N15: PPE Usage | O15: 46117
... A51: 48 | B51: SW-1021 | C51: 46374 | D51: Dec | E51: Plant A | F51: Operations | G51: Office | H51: P. Nair | I51: 22 | J51: 7 | K51: 3 | L51: Satisfactory | M51: In Progress | N51: Electrical Safety | O51: 46411

Sheet Safety Meetings
A1: 👥 SAFETY MEETINGS — DATA ENTRY | R1: Home
A2: Blue = user input · Gray = auto-calculated · use dropdowns where available
A3: S.No | B3: Meeting ID | C3: Date | D3: Month | E3: Frequency | F3: Topic/Agenda | G3: Department | H3: Chaired By | I3: Invited | J3: Attended | K3: Attendance % | L3: Duration (min) | M3: Action Items Raised | N3: Actions Closed | O3: Close-out % | P3: MoM Circulated
A4: 1 | B4: SM-1001 | C4: 46046 | D4: Jan | E4: Weekly | F4: LOTO | G4: Projects | H4: G. Das | I4: 52 | J4: 19 | K4: =IFERROR(J4/I4*100,0) -> 0 | L4: 109 | M4: 2 | N4: 2 | O4: =IFERROR(N4/M4*100,0) -> 0 | P4: Yes
A5: 2 | B5: SM-1012 | C5: 46032 | D5: Jan | E5: Annual | F5: Hot Work | G5: Projects | H5: R. Verma | I5: 40 | J5: 45 | K5: =IFERROR(J5/I5*100,0) -> 0 | L5: 48 | M5: 0 | N5: 4 | O5: =IFERROR(N5/M5*100,0) -> 0 | P5: Yes
A6: 3 | B6: SM-1015 | C6: 46078 | D6: Feb | E6: Weekly | F6: LOTO | G6: Logistics | H6: H. Patel | I6: 37 | J6: 11 | K6: =IFERROR(J6/I6*100,0) -> 0 | L6: 36 | M6: 1 | N6: 3 | O6: =IFERROR(N6/M6*100,0) -> 0 | P6: Yes
A7: 4 | B7: SM-1016 | C7: 46056 | D7: Feb | E7: Quarterly | F7: Chemical Safety | G7: Maintenance | H7: P. Nair | I7: 49 | J7: 29 | K7: =IFERROR(J7/I7*100,0) -> 0 | L7: 111 | M7: 5 | N7: 7 | O7: =IFERROR(N7/M7*100,0) -> 0 | P7: Yes
A8: 5 | B8: SM-1028 | C8: 46080 | D8: Feb | E8: Monthly | F8: Machine Guarding | G8: Admin | H8: K. Reddy | I8: 41 | J8: 51 | K8: =IFERROR(J8/I8*100,0) -> 0 | L8: 99 | M8: 2 | N8: 0 | O8: =IFERROR(N8/M8*100,0) -> 0 | P8: No
A9: 6 | B9: SM-1029 | C9: 46054 | D9: Feb | E9: Monthly | F9: Housekeeping | G9: Maintenance | H9: S. Iyer | I9: 41 | J9: 10 | K9: =IFERROR(J9/I9*100,0) -> 0 | L9: 40 | M9: 0 | N9: 4 | O9: =IFERROR(N9/M9*100,0) -> 0 | P9: No
A10: 7 | B10: SM-1030 | C10: 46077 | D10: Feb | E10: Annual | F10: Housekeeping | G10: Projects | H10: N. Gupta | I10: 29 | J10: 15 | K10: =IFERROR(J10/I10*100,0) -> 0 | L10: 55 | M10: 5 | N10: 3 | O10: =IFERROR(N10/M10*100,0) -> 0 | P10: No
A11: 8 | B11: SM-1037 | C11: 46071 | D11: Feb | E11: Annual | F11: Hot Work | G11: Safety | H11: J. Mehta | I11: 51 | J11: 53 | K11: =IFERROR(J11/I11*100,0) -> 0 | L11: 95 | M11: 8 | N11: 4 | O11: =IFERROR(N11/M11*100,0) -> 0 | P11: Yes
A12: 9 | B12: SM-1002 | C12: 46104 | D12: Mar | E12: Quarterly | F12: Housekeeping | G12: Safety | H12: K. Reddy | I12: 10 | J12: 30 | K12: =IFERROR(J12/I12*100,0) -> 0 | L12: 48 | M12: 3 | N12: 4 | O12: =IFERROR(N12/M12*100,0) -> 0 | P12: No
A13: 10 | B13: SM-1003 | C13: 46092 | D13: Mar | E13: Weekly | F13: Hot Work | G13: Construction | H13: S. Iyer | I13: 10 | J13: 17 | K13: =IFERROR(J13/I13*100,0) -> 0 | L13: 104 | M13: 4 | N13: 1 | O13: =IFERROR(N13/M13*100,0) -> 0 | P13: Yes
A14: 11 | B14: SM-1007 | C14: 46109 | D14: Mar | E14: Quarterly | F14: Confined Space | G14: Projects | H14: V. Rao | I14: 13 | J14: 39 | K14: =IFERROR(J14/I14*100,0) -> 0 | L14: 116 | M14: 3 | N14: 0 | O14: =IFERROR(N14/M14*100,0) -> 0 | P14: No
A15: 12 | B15: SM-1020 | C15: 46108 | D15: Mar | E15: Monthly | F15: LOTO | G15: Construction | H15: K. Reddy | I15: 13 | J15: 14 | K15: =IFERROR(J15/I15*100,0) -> 0 | L15: 109 | M15: 7 | N15: 8 | O15: =IFERROR(N15/M15*100,0) -> 0 | P15: Yes
... A51: 48 | B51: SM-1045 | C51: 46358 | D51: Dec | E51: Monthly | F51: Confined Space | G51: Operations | H51: N. Gupta | I51: 40 | J51: 45 | K51: =IFERROR(J51/I51*100,0) -> 0 | L51: 25 | M51: 5 | N51: 4 | O51: =IFERROR(N51/M51*100,0) -> 0 | P51: No
K52: =IFERROR(J52/I52*100,0) -> 0 | O52: =IFERROR(N52/M52*100,0) -> 0
K53: =IFERROR(J53/I53*100,0) -> 0 | O53: =IFERROR(N53/M53*100,0) -> 0
K54: =IFERROR(J54/I54*100,0) -> 0 | O54: =IFERROR(N54/M54*100,0) -> 0
K55: =IFERROR(J55/I55*100,0) -> 0 | O55: =IFERROR(N55/M55*100,0) -> 0
K56: =IFERROR(J56/I56*100,0) -> 0 | O56: =IFERROR(N56/M56*100,0) -> 0
K57: =IFERROR(J57/I57*100,0) -> 0 | O57: =IFERROR(N57/M57*100,0) -> 0
K58: =IFERROR(J58/I58*100,0) -> 0 | O58: =IFERROR(N58/M58*100,0) -> 0
K59: =IFERROR(J59/I59*100,0) -> 0 | O59: =IFERROR(N59/M59*100,0) -> 0
K60: =IFERROR(J60/I60*100,0) -> 0 | O60: =IFERROR(N60/M60*100,0) -> 0
K61: =IFERROR(J61/I61*100,0) -> 0 | O61: =IFERROR(N61/M61*100,0) -> 0
K62: =IFERROR(J62/I62*100,0) -> 0 | O62: =IFERROR(N62/M62*100,0) -> 0
K63: =IFERROR(J63/I63*100,0) -> 0 | O63: =IFERROR(N63/M63*100,0) -> 0
... K1003: =IFERROR(J1003/I1003*100,0) -> 0 | O1003: =IFERROR(N1003/M1003*100,0) -> 0

Sheet Safety Bulletins
A1: 📢 SAFETY BULLETINS — DATA ENTRY | P1: Home
A2: Blue = user input · Gray = auto-calculated · use dropdowns where available
A3: S.No | B3: Bulletin No. | C3: Date Issued | D3: Month | E3: Type | F3: Subject/Title | G3: Target Audience | H3: Issued By | I3: Distribution Method | J3: Priority | K3: Status | L3: Target Reach | M3: Actual Reach | N3: Reach %
A4: 1 | B4: SB-1002 | C4: 46036 | D4: Jan | E4: Lesson Learned | F4: Manual Handling | G4: Loading Bay | H4: A. Sharma | I4: Notice Board | J4: Low | K4: Closed | L4: 44 | M4: 26 | N4: =IFERROR(M4/L4*100,0) -> 0
A5: 2 | B5: SB-1005 | C5: 46029 | D5: Jan | E5: Best Practice | F5: LOTO | G5: Loading Bay | H5: L. Fernandes | I5: App Notification | J5: Low | K5: Closed | L5: 60 | M5: 24 | N5: =IFERROR(M5/L5*100,0) -> 0
A6: 3 | B6: SB-1017 | C6: 46047 | D6: Jan | E6: Lesson Learned | F6: Chemical Safety | G6: Field Site | H6: M. Khan | I6: Notice Board | J6: Medium | K6: Closed | L6: 16 | M6: 33 | N6: =IFERROR(M6/L6*100,0) -> 0
A7: 4 | B7: SB-1028 | C7: 46025 | D7: Jan | E7: Toolbox Topic | F7: Manual Handling | G7: ETP Plant | H7: T. Bose | I7: All Channels | J7: Critical | K7: Acknowledged | L7: 17 | M7: 46 | N7: =IFERROR(M7/L7*100,0) -> 0
A8: 5 | B8: SB-1023 | C8: 46058 | D8: Feb | E8: Toolbox Topic | F8: LOTO | G8: ETP Plant | H8: A. Sharma | I8: Notice Board | J8: High | K8: Closed | L8: 41 | M8: 41 | N8: =IFERROR(M8/L8*100,0) -> 0
A9: 6 | B9: SB-1026 | C9: 46058 | D9: Feb | E9: Safety Alert | F9: Working at Heights | G9: ETP Plant | H9: N. Gupta | I9: Notice Board | J9: High | K9: Issued | L9: 30 | M9: 16 | N9: =IFERROR(M9/L9*100,0) -> 0
A10: 7 | B10: SB-1029 | C10: 46074 | D10: Feb | E10: Advisory | F10: Working at Heights | G10: Tank Farm | H10: N. Gupta | I10: Notice Board | J10: Critical | K10: Acknowledged | L10: 25 | M10: 16 | N10: =IFERROR(M10/L10*100,0) -> 0
A11: 8 | B11: SB-1030 | C11: 46060 | D11: Feb | E11: Toolbox Topic | F11: Machine Guarding | G11: Tank Farm | H11: R. Verma | I11: All Channels | J11: Low | K11: Closed | L11: 56 | M11: 55 | N11: =IFERROR(M11/L11*100,0) -> 0
A12: 9 | B12: SB-1032 | C12: 46080 | D12: Feb | E12: Advisory | F12: Heat Stress | G12: Warehouse | H12: A. Sharma | I12: Notice Board | J12: Critical | K12: Issued | L12: 25 | M12: 18 | N12: =IFERROR(M12/L12*100,0) -> 0
A13: 10 | B13: SB-1009 | C13: 46096 | D13: Mar | E13: Advisory | F13: Working at Heights | G13: Control Room | H13: K. Reddy | I13: App Notification | J13: Critical | K13: Closed | L13: 38 | M13: 23 | N13: =IFERROR(M13/L13*100,0) -> 0
A14: 11 | B14: SB-1014 | C14: 46092 | D14: Mar | E14: Bulletin | F14: LOTO | G14: Admin Block | H14: H. Patel | I14: All Channels | J14: Medium | K14: Closed | L14: 44 | M14: 23 | N14: =IFERROR(M14/L14*100,0) -> 0
A15: 12 | B15: SB-1016 | C15: 46099 | D15: Mar | E15: Advisory | F15: LOTO | G15: Tank Farm | H15: S. Iyer | I15: App Notification | J15: Medium | K15: Issued | L15: 41 | M15: 53 | N15: =IFERROR(M15/L15*100,0) -> 0
... A51: 48 | B51: SB-1015 | C51: 46371 | D51: Dec | E51: Advisory | F51: Slip Trip Fall | G51: Workshop | H51: N. Gupta | I51: All Channels | J51: Medium | K51: Acknowledged | L51: 57 | M51: 44 | N51: =IFERROR(M51/L51*100,0) -> 0
N52: =IFERROR(M52/L52*100,0) -> 0
N53: =IFERROR(M53/L53*100,0) -> 0
N54: =IFERROR(M54/L54*100,0) -> 0
N55: =IFERROR(M55/L55*100,0) -> 0
N56: =IFERROR(M56/L56*100,0) -> 0
N57: =IFERROR(M57/L57*100,0) -> 0
N58: =IFERROR(M58/L58*100,0) -> 0
N59: =IFERROR(M59/L59*100,0) -> 0
N60: =IFERROR(M60/L60*100,0) -> 0
N61: =IFERROR(M61/L61*100,0) -> 0
N62: =IFERROR(M62/L62*100,0) -> 0
N63: =IFERROR(M63/L63*100,0) -> 0
... N1003: =IFERROR(M1003/L1003*100,0) -> 0

Sheet Emergency Drills
A1: 🚨 EMERGENCY DRILLS — DATA ENTRY | Q1: Home
A2: Blue = user input · Gray = auto-calculated · use dropdowns where available
A3: S.No | B3: Drill ID | C3: Date | D3: Month | E3: Drill Type | F3: Location | G3: Drill Leader | H3: Target Participants | I3: Actual Participants | J3: Participation % | K3: Target Response (min) | L3: Actual Response (min) | M3: Overall Rating | N3: Improvement Areas | O3: Status
A4: 1 | B4: ED-1007 | C4: 46035 | D4: Jan | E4: Fire Evacuation | F4: Control Room | G4: M. Khan | H4: 26 | I4: 31 | J4: =IFERROR(I4/H4*100,0) -> 0 | K4: 27 | L4: 8 | M4: Needs Improvement | N4: Plant B | O4: Action Pending
A5: 2 | B5: ED-1030 | C5: 46049 | D5: Jan | E5: Medical Emergency | F5: Office | G5: D. Singh | H5: 26 | I5: 29 | J5: =IFERROR(I5/H5*100,0) -> 0 | K5: 20 | L5: 18 | M5: Satisfactory | N5: ETP Plant | O5: Completed
A6: 3 | B6: ED-1041 | C6: 46045 | D6: Jan | E6: Fire Evacuation | F6: Warehouse | G6: K. Reddy | H6: 44 | I6: 25 | J6: =IFERROR(I6/H6*100,0) -> 0 | K6: 9 | L6: 17 | M6: Unsatisfactory | N6: Control Room | O6: Completed
A7: 4 | B7: ED-1002 | C7: 46068 | D7: Feb | E7: Gas Leak | F7: Tank Farm | G7: D. Singh | H7: 33 | I7: 21 | J7: =IFERROR(I7/H7*100,0) -> 0 | K7: 25 | L7: 24 | M7: Satisfactory | N7: ETP Plant | O7: Completed
A8: 5 | B8: ED-1003 | C8: 46069 | D8: Feb | E8: Medical Emergency | F8: Loading Bay | G8: R. Verma | H8: 15 | I8: 59 | J8: =IFERROR(I8/H8*100,0) -> 0 | K8: 10 | L8: 15 | M8: Needs Improvement | N8: Office | O8: Action Pending
A9: 6 | B9: ED-1008 | C9: 46074 | D9: Feb | E9: Chemical Spill | F9: Control Room | G9: L. Fernandes | H9: 38 | I9: 25 | J9: =IFERROR(I9/H9*100,0) -> 0 | K9: 26 | L9: 12 | M9: Excellent | N9: Tank Farm | O9: Action Pending
A10: 7 | B10: ED-1025 | C10: 46093 | D10: Mar | E10: Gas Leak | F10: Admin Block | G10: A. Sharma | H10: 26 | I10: 58 | J10: =IFERROR(I10/H10*100,0) -> 0 | K10: 1 | L10: 4 | M10: Needs Improvement | N10: Admin Block | O10: Action Pending
A11: 8 | B11: ED-1028 | C11: 46098 | D11: Mar | E11: Chemical Spill | F11: Office | G11: L. Fernandes | H11: 53 | I11: 35 | J11: =IFERROR(I11/H11*100,0) -> 0 | K11: 22 | L11: 19 | M11: Needs Improvement | N11: Control Room | O11: Completed
A12: 9 | B12: ED-1045 | C12: 46107 | D12: Mar | E12: Medical Emergency | F12: Field Site | G12: H. Patel | H12: 42 | I12: 36 | J12: =IFERROR(I12/H12*100,0) -> 0 | K12: 18 | L12: 4 | M12: Satisfactory | N12: Warehouse | O12: Completed
A13: 10 | B13: ED-1010 | C13: 46117 | D13: Apr | E13: Fire Evacuation | F13: ETP Plant | G13: H. Patel | H13: 34 | I13: 58 | J13: =IFERROR(I13/H13*100,0) -> 0 | K13: 15 | L13: 1 | M13: Needs Improvement | N13: Admin Block | O13: Completed
A14: 11 | B14: ED-1013 | C14: 46136 | D14: Apr | E14: Earthquake | F14: ETP Plant | G14: N. Gupta | H14: 42 | I14: 57 | J14: =IFERROR(I14/H14*100,0) -> 0 | K14: 14 | L14: 30 | M14: Needs Improvement | N14: Tank Farm | O14: Completed
A15: 12 | B15: ED-1019 | C15: 46132 | D15: Apr | E15: Earthquake | F15: Plant A | G15: J. Mehta | H15: 11 | I15: 44 | J15: =IFERROR(I15/H15*100,0) -> 0 | K15: 29 | L15: 0 | M15: Satisfactory | N15: Admin Block | O15: Completed
... A51: 48 | B51: ED-1043 | C51: 46384 | D51: Dec | E51: Earthquake | F51: Warehouse | G51: G. Das | H51: 17 | I51: 14 | J51: =IFERROR(I51/H51*100,0) -> 0 | K51: 18 | L51: 15 | M51: Satisfactory | N51: ETP Plant | O51: Action Pending
J52: =IFERROR(I52/H52*100,0) -> 0
J53: =IFERROR(I53/H53*100,0) -> 0
J54: =IFERROR(I54/H54*100,0) -> 0
J55: =IFERROR(I55/H55*100,0) -> 0
J56: =IFERROR(I56/H56*100,0) -> 0
J57: =IFERROR(I57/H57*100,0) -> 0
J58: =IFERROR(I58/H58*100,0) -> 0
J59: =IFERROR(I59/H59*100,0) -> 0
J60: =IFERROR(I60/H60*100,0) -> 0
J61: =IFERROR(I61/H61*100,0) -> 0
J62: =IFERROR(I62/H62*100,0) -> 0
J63: =IFERROR(I63/H63*100,0) -> 0
... J1003: =IFERROR(I1003/H1003*100,0) -> 0

Sheet Internal Audits
A1: 📋 INTERNAL AUDITS — DATA ENTRY | R1: Home
A2: Blue = user input · Gray = auto-calculated · use dropdowns where available
A3: S.No | B3: Audit No. | C3: Date | D3: Month | E3: Audit Scope | F3: Audit Type | G3: Department | H3: Location | I3: Lead Auditor | J3: Approved By | K3: Checklist Items | L3: Minor NC | M3: Major NC | N3: Observations | O3: Recommendations | P3: Status
A4: 1 | B4: IA-1006 | C4: 46031 | D4: Jan | E4: Fire Safety | F4: Customer Audit | G4: Engineering | H4: Plant A | I4: K. Reddy | J4: G. Das | K4: Working at Heights | L4: 7 | M4: 1 | N4: 7 | O4: 4 | P4: Scheduled
A5: 2 | B5: IA-1008 | C5: 46042 | D5: Jan | E5: Manual Handling | F5: Regulatory Inspection | G5: Admin | H5: Loading Bay | I5: G. Das | J5: A. Sharma | K5: Emergency Procedures | L5: 2 | M5: 1 | N5: 6 | O5: 5 | P5: Completed
A6: 3 | B6: IA-1014 | C6: 46026 | D6: Jan | E6: Machine Guarding | F6: System Audit | G6: Maintenance | H6: Admin Block | I6: A. Sharma | J6: L. Fernandes | K6: Housekeeping | L6: 3 | M6: 1 | N6: 7 | O6: 3 | P6: Completed
A7: 4 | B7: IA-1022 | C7: 46037 | D7: Jan | E7: Electrical Safety | F7: Process Audit | G7: Operations | H7: Boiler House | I7: R. Verma | J7: H. Patel | K7: Emergency Procedures | L7: 4 | M7: 8 | N7: 0 | O7: 8 | P7: Completed
A8: 5 | B8: IA-1031 | C8: 46047 | D8: Jan | E8: Hot Work | F8: Process Audit | G8: Projects | H8: Field Site | I8: G. Das | J8: A. Sharma | K8: Electrical Safety | L8: 8 | M8: 5 | N8: 0 | O8: 1 | P8: Completed
A9: 6 | B9: IA-1002 | C9: 46056 | D9: Feb | E9: LOTO | F9: Process Audit | G9: Quality | H9: ETP Plant | I9: G. Das | J9: V. Rao | K9: Manual Handling | L9: 5 | M9: 4 | N9: 0 | O9: 5 | P9: Completed
A10: 7 | B10: IA-1020 | C10: 46075 | D10: Feb | E10: PPE Usage | F10: Customer Audit | G10: Construction | H10: Office | I10: M. Khan | J10: J. Mehta | K10: Working at Heights | L10: 7 | M10: 7 | N10: 0 | O10: 0 | P10: In Progress
A11: 8 | B11: IA-1021 | C11: 46068 | D11: Feb | E11: Confined Space | F11: Surveillance | G11: Engineering | H11: Plant B | I11: T. Bose | J11: V. Rao | K11: Fire Safety | L11: 7 | M11: 5 | N11: 5 | O11: 8 | P11: Scheduled
A12: 9 | B12: IA-1025 | C12: 46080 | D12: Feb | E12: Machine Guarding | F12: Process Audit | G12: Operations | H12: ETP Plant | I12: T. Bose | J12: N. Gupta | K12: Slip Trip Fall | L12: 0 | M12: 4 | N12: 3 | O12: 3 | P12: In Progress
A13: 10 | B13: IA-1012 | C13: 46087 | D13: Mar | E13: PPE Usage | F13: Process Audit | G13: Maintenance | H13: Admin Block | I13: D. Singh | J13: D. Singh | K13: Confined Space | L13: 7 | M13: 8 | N13: 0 | O13: 5 | P13: Completed
A14: 11 | B14: IA-1023 | C14: 46086 | D14: Mar | E14: Working at Heights | F14: Regulatory Inspection | G14: Logistics | H14: Admin Block | I14: J. Mehta | J14: G. Das | K14: Chemical Safety | L14: 3 | M14: 6 | N14: 5 | O14: 4 | P14: Completed
A15: 12 | B15: IA-1030 | C15: 46087 | D15: Mar | E15: Manual Handling | F15: Surveillance | G15: Maintenance | H15: Tank Farm | I15: L. Fernandes | J15: J. Mehta | K15: Chemical Safety | L15: 1 | M15: 1 | N15: 8 | O15: 5 | P15: Scheduled
... A51: 48 | B51: IA-1037 | C51: 46361 | D51: Dec | E51: Hot Work | F51: Compliance Audit | G51: Logistics | H51: Loading Bay | I51: D. Singh | J51: N. Gupta | K51: Chemical Safety | L51: 7 | M51: 7 | N51: 3 | O51: 3 | P51: In Progress

Sheet External Audits
A1: 🏛️ EXTERNAL AUDITS — DATA ENTRY | R1: Home
A2: Blue = user input · Gray = auto-calculated · use dropdowns where available
A3: S.No | B3: Audit No. | C3: Date | D3: Month | E3: Audit Scope | F3: Audit Type | G3: Department | H3: Location | I3: Lead Auditor | J3: Approved By | K3: Checklist Items | L3: Minor NC | M3: Major NC | N3: Observations | O3: Recommendations | P3: Status
A4: 1 | B4: EA-1002 | C4: 46037 | D4: Jan | E4: Heat Stress | F4: Process Audit | G4: Operations | H4: Office | I4: L. Fernandes | J4: S. Iyer | K4: PPE Usage | L4: 6 | M4: 8 | N4: 3 | O4: 8 | P4: Completed
A5: 2 | B5: EA-1010 | C5: 46050 | D5: Jan | E5: Fire Safety | F5: Compliance Audit | G5: Quality | H5: Warehouse | I5: A. Sharma | J5: T. Bose | K5: Housekeeping | L5: 4 | M5: 1 | N5: 7 | O5: 3 | P5: In Progress
A6: 3 | B6: EA-1022 | C6: 46039 | D6: Jan | E6: LOTO | F6: Process Audit | G6: Admin | H6: Tank Farm | I6: A. Sharma | J6: R. Verma | K6: Confined Space | L6: 7 | M6: 3 | N6: 1 | O6: 6 | P6: Completed
A7: 4 | B7: EA-1030 | C7: 46044 | D7: Jan | E7: Housekeeping | F7: Compliance Audit | G7: Operations | H7: Plant A | I7: K. Reddy | J7: K. Reddy | K7: Manual Handling | L7: 4 | M7: 8 | N7: 5 | O7: 3 | P7: In Progress
A8: 5 | B8: EA-1041 | C8: 46048 | D8: Jan | E8: Fire Safety | F8: Surveillance | G8: Quality | H8: Workshop | I8: L. Fernandes | J8: D. Singh | K8: Confined Space | L8: 2 | M8: 2 | N8: 6 | O8: 3 | P8: In Progress
A9: 6 | B9: EA-1021 | C9: 46078 | D9: Feb | E9: Housekeeping | F9: Surveillance | G9: Logistics | H9: Warehouse | I9: P. Nair | J9: D. Singh | K9: Slip Trip Fall | L9: 6 | M9: 3 | N9: 3 | O9: 0 | P9: Completed
A10: 7 | B10: EA-1024 | C10: 46060 | D10: Feb | E10: Hot Work | F10: Compliance Audit | G10: Logistics | H10: Boiler House | I10: V. Rao | J10: S. Iyer | K10: Housekeeping | L10: 1 | M10: 8 | N10: 0 | O10: 6 | P10: Completed
A11: 8 | B11: EA-1026 | C11: 46069 | D11: Feb | E11: Emergency Procedures | F11: Process Audit | G11: Quality | H11: Tank Farm | I11: S. Iyer | J11: G. Das | K11: LOTO | L11: 3 | M11: 1 | N11: 5 | O11: 7 | P11: Completed
A12: 9 | B12: EA-1013 | C12: 46100 | D12: Mar | E12: Hot Work | F12: Customer Audit | G12: Quality | H12: Office | I12: J. Mehta | J12: J. Mehta | K12: Manual Handling | L12: 6 | M12: 4 | N12: 6 | O12: 0 | P12: Completed
A13: 10 | B13: EA-1019 | C13: 46082 | D13: Mar | E13: Hot Work | F13: Regulatory Inspection | G13: Safety | H13: Control Room | I13: M. Khan | J13: L. Fernandes | K13: Housekeeping | L13: 2 | M13: 0 | N13: 8 | O13: 3 | P13: Completed
A14: 11 | B14: EA-1028 | C14: 46089 | D14: Mar | E14: Fire Safety | F14: Customer Audit | G14: Maintenance | H14: Admin Block | I14: T. Bose | J14: G. Das | K14: Emergency Procedures | L14: 4 | M14: 2 | N14: 4 | O14: 2 | P14: Completed
A15: 12 | B15: EA-1040 | C15: 46084 | D15: Mar | E15: Emergency Procedures | F15: Customer Audit | G15: Construction | H15: Workshop | I15: M. Khan | J15: G. Das | K15: Confined Space | L15: 2 | M15: 2 | N15: 2 | O15: 0 | P15: Completed
... A51: 48 | B51: EA-1031 | C51: 46378 | D51: Dec | E51: LOTO | F51: Surveillance | G51: Safety | H51: Workshop | I51: G. Das | J51: P. Nair | K51: Confined Space | L51: 3 | M51: 8 | N51: 8 | O51: 7 | P51: Completed

Sheet Management Visits
A1: 🤝 MANAGEMENT VISITS — DATA ENTRY | P1: Home
A2: Blue = user input · Gray = auto-calculated · use dropdowns where available
A3: S.No | B3: Visit ID | C3: Date | D3: Month | E3: Visit Type | F3: Department | G3: Location | H3: Visited By | I3: Duration (min) | J3: Observations Made | K3: Actions Raised | L3: Actions Closed | M3: Close-out % | N3: Status
A4: 1 | B4: MV-1001 | C4: 46031 | D4: Jan | E4: Safety Observation | F4: Projects | G4: Plant B | H4: P. Nair | I4: 99 | J4: 4 | K4: 3 | L4: 2 | M4: =IFERROR(L4/K4*100,0) -> 0 | N4: Completed
A5: 2 | B5: MV-1026 | C5: 46046 | D5: Jan | E5: Safety Observation | F5: Safety | G5: Workshop | H5: H. Patel | I5: 24 | J5: 2 | K5: 5 | L5: 7 | M5: =IFERROR(L5/K5*100,0) -> 0 | N5: Completed
A6: 3 | B6: MV-1037 | C6: 46023 | D6: Jan | E6: Site Walk | F6: Logistics | G6: Boiler House | H6: S. Iyer | I6: 19 | J6: 5 | K6: 5 | L6: 1 | M6: =IFERROR(L6/K6*100,0) -> 0 | N6: Completed
A7: 4 | B7: MV-1043 | C7: 46038 | D7: Jan | E7: Project Visit | F7: Quality | G7: ETP Plant | H7: H. Patel | I7: 120 | J7: 7 | K7: 7 | L7: 8 | M7: =IFERROR(L7/K7*100,0) -> 0 | N7: Completed
A8: 5 | B8: MV-1007 | C8: 46060 | D8: Feb | E8: Safety Observation | F8: Quality | G8: Loading Bay | H8: D. Singh | I8: 114 | J8: 0 | K8: 2 | L8: 6 | M8: =IFERROR(L8/K8*100,0) -> 0 | N8: Action Pending
A9: 6 | B9: MV-1010 | C9: 46081 | D9: Feb | E9: Plant Visit | F9: Maintenance | G9: Workshop | H9: K. Reddy | I9: 66 | J9: 4 | K9: 3 | L9: 2 | M9: =IFERROR(L9/K9*100,0) -> 0 | N9: Action Pending
A10: 7 | B10: MV-1012 | C10: 46072 | D10: Feb | E10: Plant Visit | F10: Contractor | G10: ETP Plant | H10: A. Sharma | I10: 68 | J10: 0 | K10: 7 | L10: 1 | M10: =IFERROR(L10/K10*100,0) -> 0 | N10: Completed
A11: 8 | B11: MV-1020 | C11: 46062 | D11: Feb | E11: Safety Observation | F11: Maintenance | G11: Boiler House | H11: R. Verma | I11: 28 | J11: 4 | K11: 6 | L11: 2 | M11: =IFERROR(L11/K11*100,0) -> 0 | N11: Completed
A12: 9 | B12: MV-1023 | C12: 46058 | D12: Feb | E12: Safety Observation | F12: Contractor | G12: Loading Bay | H12: V. Rao | I12: 57 | J12: 0 | K12: 3 | L12: 4 | M12: =IFERROR(L12/K12*100,0) -> 0 | N12: Completed
A13: 10 | B13: MV-1024 | C13: 46061 | D13: Feb | E13: Project Visit | F13: Safety | G13: Office | H13: M. Khan | I13: 102 | J13: 6 | K13: 6 | L13: 8 | M13: =IFERROR(L13/K13*100,0) -> 0 | N13: Completed
A14: 11 | B14: MV-1047 | C14: 46065 | D14: Feb | E14: Safety Observation | F14: Engineering | G14: Plant B | H14: P. Nair | I14: 69 | J14: 8 | K14: 0 | L14: 4 | M14: =IFERROR(L14/K14*100,0) -> 0 | N14: Completed
A15: 12 | B15: MV-1005 | C15: 46106 | D15: Mar | E15: Safety Observation | F15: Operations | G15: Office | H15: S. Iyer | I15: 73 | J15: 1 | K15: 2 | L15: 4 | M15: =IFERROR(L15/K15*100,0) -> 0 | N15: Completed
... A51: 48 | B51: MV-1042 | C51: 46346 | D51: Nov | E51: Project Visit | F51: Admin | G51: Plant B | H51: H. Patel | I51: 21 | J51: 5 | K51: 4 | L51: 6 | M51: =IFERROR(L51/K51*100,0) -> 0 | N51: Completed
M52: =IFERROR(L52/K52*100,0) -> 0
M53: =IFERROR(L53/K53*100,0) -> 0
M54: =IFERROR(L54/K54*100,0) -> 0
M55: =IFERROR(L55/K55*100,0) -> 0
M56: =IFERROR(L56/K56*100,0) -> 0
M57: =IFERROR(L57/K57*100,0) -> 0
M58: =IFERROR(L58/K58*100,0) -> 0
M59: =IFERROR(L59/K59*100,0) -> 0
M60: =IFERROR(L60/K60*100,0) -> 0
M61: =IFERROR(L61/K61*100,0) -> 0
M62: =IFERROR(L62/K62*100,0) -> 0
M63: =IFERROR(L63/K63*100,0) -> 0
... M1003: =IFERROR(L1003/K1003*100,0) -> 0

Sheet Management Reviews
A1: 🧭 MANAGEMENT REVIEWS — DATA ENTRY | Q1: Home
A2: Blue = user input · Gray = auto-calculated · use dropdowns where available
A3: S.No | B3: Review ID | C3: Date | D3: Month | E3: Review Topic | F3: Chaired By | G3: Members Invited | H3: Members Attended | I3: Attendance % | J3: Duration (min) | K3: Decisions Made | L3: Actions Assigned | M3: Close-out % | N3: MoM Distributed | O3: Status
A4: 1 | B4: MR-1045 | C4: 46029 | D4: Jan | E4: LOTO | F4: M. Khan | G4: 33 | H4: 53 | I4: =IFERROR(H4/G4*100,0) -> 0 | J4: 37 | K4: 1 | L4: P. Nair | N4: No | O4: Completed
A5: 2 | B5: MR-1009 | C5: 46059 | D5: Feb | E5: Confined Space | F5: J. Mehta | G5: 48 | H5: 56 | I5: =IFERROR(H5/G5*100,0) -> 0 | J5: 99 | K5: 7 | L5: T. Bose | N5: Yes | O5: In Progress
A6: 3 | B6: MR-1023 | C6: 46070 | D6: Feb | E6: Confined Space | F6: A. Sharma | G6: 20 | H6: 27 | I6: =IFERROR(H6/G6*100,0) -> 0 | J6: 76 | K6: 2 | L6: L. Fernandes | N6: Yes | O6: Scheduled
A7: 4 | B7: MR-1025 | C7: 46069 | D7: Feb | E7: Working at Heights | F7: D. Singh | G7: 57 | H7: 10 | I7: =IFERROR(H7/G7*100,0) -> 0 | J7: 48 | K7: 6 | L7: M. Khan | N7: Yes | O7: Completed
A8: 5 | B8: MR-1041 | C8: 46066 | D8: Feb | E8: Electrical Safety | F8: P. Nair | G8: 49 | H8: 39 | I8: =IFERROR(H8/G8*100,0) -> 0 | J8: 71 | K8: 5 | L8: M. Khan | N8: Yes | O8: Completed
A9: 6 | B9: MR-1002 | C9: 46090 | D9: Mar | E9: Fire Safety | F9: G. Das | G9: 46 | H9: 15 | I9: =IFERROR(H9/G9*100,0) -> 0 | J9: 119 | K9: 3 | L9: A. Sharma | N9: No | O9: In Progress
A10: 7 | B10: MR-1004 | C10: 46101 | D10: Mar | E10: Hot Work | F10: L. Fernandes | G10: 48 | H10: 33 | I10: =IFERROR(H10/G10*100,0) -> 0 | J10: 96 | K10: 5 | L10: T. Bose | N10: Yes | O10: In Progress
A11: 8 | B11: MR-1005 | C11: 46084 | D11: Mar | E11: Manual Handling | F11: K. Reddy | G11: 26 | H11: 28 | I11: =IFERROR(H11/G11*100,0) -> 0 | J11: 43 | K11: 3 | L11: P. Nair | N11: Yes | O11: Scheduled
A12: 9 | B12: MR-1012 | C12: 46082 | D12: Mar | E12: Fire Safety | F12: T. Bose | G12: 26 | H12: 46 | I12: =IFERROR(H12/G12*100,0) -> 0 | J12: 19 | K12: 0 | L12: S. Iyer | N12: Yes | O12: In Progress
A13: 10 | B13: MR-1024 | C13: 46094 | D13: Mar | E13: Heat Stress | F13: G. Das | G13: 42 | H13: 53 | I13: =IFERROR(H13/G13*100,0) -> 0 | J13: 47 | K13: 4 | L13: V. Rao | N13: No | O13: Completed
A14: 11 | B14: MR-1028 | C14: 46101 | D14: Mar | E14: Emergency Procedures | F14: D. Singh | G14: 40 | H14: 20 | I14: =IFERROR(H14/G14*100,0) -> 0 | J14: 56 | K14: 7 | L14: T. Bose | N14: No | O14: Completed
A15: 12 | B15: MR-1034 | C15: 46086 | D15: Mar | E15: Electrical Safety | F15: R. Verma | G15: 39 | H15: 56 | I15: =IFERROR(H15/G15*100,0) -> 0 | J15: 42 | K15: 0 | L15: R. Verma | N15: No | O15: Completed
... A51: 48 | B51: MR-1011 | C51: 46376 | D51: Dec | E51: Fire Safety | F51: T. Bose | G51: 10 | H51: 33 | I51: =IFERROR(H51/G51*100,0) -> 0 | J51: 73 | K51: 2 | L51: A. Sharma | N51: Yes | O51: Completed
I52: =IFERROR(H52/G52*100,0) -> 0
I53: =IFERROR(H53/G53*100,0) -> 0
I54: =IFERROR(H54/G54*100,0) -> 0
I55: =IFERROR(H55/G55*100,0) -> 0
I56: =IFERROR(H56/G56*100,0) -> 0
I57: =IFERROR(H57/G57*100,0) -> 0
I58: =IFERROR(H58/G58*100,0) -> 0
I59: =IFERROR(H59/G59*100,0) -> 0
I60: =IFERROR(H60/G60*100,0) -> 0
I61: =IFERROR(H61/G61*100,0) -> 0
I62: =IFERROR(H62/G62*100,0) -> 0
I63: =IFERROR(H63/G63*100,0) -> 0
... I1003: =IFERROR(H1003/G1003*100,0) -> 0

Sheet Disciplinary Actions
A1: ⚖️ DISCIPLINARY ACTIONS — DATA ENTRY | M1: Home
A2: Blue = user input · Gray = auto-calculated · use dropdowns where available
A3: S.No | B3: Case No. | C3: Date | D3: Month | E3: Violation Type | F3: Department | G3: Employee Name | H3: Action Taken | I3: Offense Level | J3: Approved By | K3: Status
A4: 1 | B4: DA-1021 | C4: 46050 | D4: Jan | E4: Substance Abuse | F4: Safety | G4: V. Rao | H4: Termination | I4: 1st Offense | J4: P. Nair | K4: Under Review
A5: 2 | B5: DA-1022 | C5: 46041 | D5: Jan | E5: Substance Abuse | F5: Quality | G5: T. Bose | H5: Suspension | I5: 3rd Offense | J5: L. Fernandes | K5: Appealed
A6: 3 | B6: DA-1023 | C6: 46034 | D6: Jan | E6: Reckless Behavior | F6: Safety | G6: L. Fernandes | H6: Verbal Warning | I6: 1st Offense | J6: R. Verma | K6: Completed
A7: 4 | B7: DA-1024 | C7: 46027 | D7: Jan | E7: Safety Rule Breach | F7: Operations | G7: N. Gupta | H7: Verbal Warning | I7: 2nd Offense | J7: A. Sharma | K7: Completed
A8: 5 | B8: DA-1031 | C8: 46044 | D8: Jan | E8: Reckless Behavior | F8: Construction | G8: V. Rao | H8: Written Warning | I8: 3rd Offense | J8: P. Nair | K8: Completed
A9: 6 | B9: DA-1032 | C9: 46047 | D9: Jan | E9: Reckless Behavior | F9: Maintenance | G9: M. Khan | H9: Verbal Warning | I9: Repeat | J9: K. Reddy | K9: Under Review
A10: 7 | B10: DA-1040 | C10: 46028 | D10: Jan | E10: Unauthorized Work | F10: Admin | G10: J. Mehta | H10: Termination | I10: 1st Offense | J10: M. Khan | K10: Completed
A11: 8 | B11: DA-1003 | C11: 46060 | D11: Feb | E11: Reckless Behavior | F11: Quality | G11: V. Rao | H11: Suspension | I11: 1st Offense | J11: T. Bose | K11: Completed
A12: 9 | B12: DA-1035 | C12: 46066 | D12: Feb | E12: PPE Violation | F12: Contractor | G12: N. Gupta | H12: Suspension | I12: 2nd Offense | J12: T. Bose | K12: Under Review
A13: 10 | B13: DA-1011 | C13: 46102 | D13: Mar | E13: Unauthorized Work | F13: Engineering | G13: D. Singh | H13: Written Warning | I13: 1st Offense | J13: V. Rao | K13: Completed
A14: 11 | B14: DA-1013 | C14: 46100 | D14: Mar | E14: Safety Rule Breach | F14: Logistics | G14: L. Fernandes | H14: Suspension | I14: 1st Offense | J14: T. Bose | K14: Under Review
A15: 12 | B15: DA-1018 | C15: 46093 | D15: Mar | E15: Unauthorized Work | F15: Contractor | G15: H. Patel | H15: Written Warning | I15: 1st Offense | J15: V. Rao | K15: Under Review
... A51: 48 | B51: DA-1026 | C51: 46372 | D51: Dec | E51: Safety Rule Breach | F51: Logistics | G51: G. Das | H51: Termination | I51: 1st Offense | J51: J. Mehta | K51: Completed

Sheet Safety Awards
A1: 🏆 SAFETY AWARDS — DATA ENTRY | L1: Home
A2: Blue = user input · Gray = auto-calculated · use dropdowns where available
A3: S.No | B3: Award ID | C3: Date | D3: Month | E3: Award Category | F3: Department | G3: Recipient | H3: Reward Type | I3: Presented By | J3: Status
A4: 1 | B4: AW-1010 | C4: 46026 | D4: Jan | E4: Safe Worker of Month | F4: Maintenance | G4: G. Das | H4: Cash Bonus | I4: S. Iyer | J4: Presented
A5: 2 | B5: AW-1047 | C5: 46038 | D5: Jan | E5: Safe Worker of Month | F5: Quality | G5: K. Reddy | H5: Recognition Letter | I5: J. Mehta | J5: Scheduled
A6: 3 | B6: AW-1001 | C6: 46057 | D6: Feb | E6: Best Safety Suggestion | F6: Engineering | G6: S. Iyer | H6: Gift Voucher | I6: D. Singh | J6: Scheduled
A7: 4 | B7: AW-1005 | C7: 46066 | D7: Feb | E7: Safety Innovation | F7: Contractor | G7: D. Singh | H7: Cash Bonus | I7: G. Das | J7: Scheduled
A8: 5 | B8: AW-1017 | C8: 46055 | D8: Feb | E8: Best Department | F8: Contractor | G8: N. Gupta | H8: Trophy | I8: G. Das | J8: Presented
A9: 6 | B9: AW-1025 | C9: 46073 | D9: Feb | E9: Best Safety Suggestion | F9: Construction | G9: H. Patel | H9: Cash Bonus | I9: R. Verma | J9: Scheduled
A10: 7 | B10: AW-1042 | C10: 46070 | D10: Feb | E10: Safety Innovation | F10: Construction | G10: S. Iyer | H10: Gift Voucher | I10: T. Bose | J10: Presented
A11: 8 | B11: AW-1032 | C11: 46094 | D11: Mar | E11: Zero Incident Award | F11: Operations | G11: A. Sharma | H11: Gift Voucher | I11: T. Bose | J11: Presented
A12: 9 | B12: AW-1034 | C12: 46106 | D12: Mar | E12: HSE Champion | F12: Logistics | G12: P. Nair | H12: Certificate | I12: D. Singh | J12: Nominated
A13: 10 | B13: AW-1004 | C13: 46140 | D13: Apr | E13: Best Department | F13: Projects | G13: K. Reddy | H13: Trophy | I13: D. Singh | J13: Nominated
A14: 11 | B14: AW-1011 | C14: 46119 | D14: Apr | E14: Safety Innovation | F14: Projects | G14: A. Sharma | H14: Recognition Letter | I14: K. Reddy | J14: Scheduled
A15: 12 | B15: AW-1020 | C15: 46124 | D15: Apr | E15: Best Department | F15: Safety | G15: G. Das | H15: Certificate | I15: K. Reddy | J15: Presented
... A51: 48 | B51: AW-1045 | C51: 46359 | D51: Dec | E51: Best Safety Suggestion | F51: Projects | G51: H. Patel | H51: Gift Voucher | I51: G. Das | J51: Nominated

Sheet Stop Work Authority
A1: ✋ STOP WORK AUTHORITY — DATA ENTRY | O1: Home
A2: Blue = user input · Gray = auto-calculated · use dropdowns where available
A3: S.No | B3: SWA No. | C3: Date | D3: Month | E3: Reason for Stop Work | F3: Department | G3: Location | H3: Initiated By | I3: Authorized By | J3: Downtime (min) | K3: Severity | L3: Resolution | M3: Investigation Done
A4: 1 | B4: SWA-1002 | C4: 46030 | D4: Jan | E4: Slip Trip Fall | F4: Engineering | G4: Tank Farm | H4: J. Mehta | I4: L. Fernandes | J4: 14 | K4: Critical | L4: Resolved | M4: No
A5: 2 | B5: SWA-1009 | C5: 46027 | D5: Jan | E5: Emergency Procedures | F5: Operations | G5: Tank Farm | H5: M. Khan | I5: H. Patel | J5: 6 | K5: Critical | L5: Permanent Fix Applied | M5: No
A6: 3 | B6: SWA-1011 | C6: 46025 | D6: Jan | E6: Manual Handling | F6: Engineering | G6: Workshop | H6: H. Patel | I6: D. Singh | J6: 5 | K6: Medium | L6: Resolved | M6: Yes
A7: 4 | B7: SWA-1042 | C7: 46026 | D7: Jan | E7: Emergency Procedures | F7: Logistics | G7: Warehouse | H7: S. Iyer | I7: M. Khan | J7: 15 | K7: Critical | L7: Resolved | M7: No
A8: 5 | B8: SWA-1045 | C8: 46036 | D8: Jan | E8: Hot Work | F8: Maintenance | G8: Warehouse | H8: K. Reddy | I8: J. Mehta | J8: 23 | K8: Medium | L8: Permanent Fix Applied | M8: Yes
A9: 6 | B9: SWA-1032 | C9: 46073 | D9: Feb | E9: Emergency Procedures | F9: Admin | G9: Plant A | H9: S. Iyer | I9: L. Fernandes | J9: 27 | K9: Medium | L9: Resolved | M9: Yes
A10: 7 | B10: SWA-1046 | C10: 46075 | D10: Feb | E10: Chemical Safety | F10: Projects | G10: Warehouse | H10: K. Reddy | I10: T. Bose | J10: 7 | K10: High | L10: Permanent Fix Applied | M10: No
A11: 8 | B11: SWA-1015 | C11: 46101 | D11: Mar | E11: Heat Stress | F11: Maintenance | G11: Plant A | H11: S. Iyer | I11: J. Mehta | J11: 9 | K11: High | L11: Under Investigation | M11: Yes
A12: 9 | B12: SWA-1038 | C12: 46108 | D12: Mar | E12: Heat Stress | F12: Safety | G12: Admin Block | H12: T. Bose | I12: A. Sharma | J12: 17 | K12: Medium | L12: Permanent Fix Applied | M12: Yes
